/*
*** MADE BY MITHION'S .SCHEMATIC TO JAVA CONVERTING TOOL v1.6 ***
*/

package Mrhand3.BigModBF.worldgen;
import java.util.Random;

import net.minecraft.block.Block;
import net.minecraft.world.World;
import net.minecraft.world.gen.feature.WorldGenerator;

public class WorldGenBlobShrine extends WorldGenerator
{
		public WorldGenBlobShrine() { }

	public boolean generate(World world, Random rand, int i, int j, int k) {
		if (world.rand.nextInt(10) == 0)
        {
                while (world.isAirBlock(i, j, k) && j > 55)
                {
                        --j;
                }
        		world.setBlock(i + 1, j + 0, k + 1, Block.sandStone.blockID);
        		world.setBlock(i + 1, j + 0, k + 2, Block.sandStone.blockID);
        		world.setBlock(i + 1, j + 0, k + 3, Block.sandStone.blockID);
        		world.setBlock(i + 1, j + 0, k + 4, Block.sandStone.blockID);
        		world.setBlock(i + 1, j + 0, k + 5, Block.sandStone.blockID);
        		world.setBlock(i + 1, j + 0, k + 6, Block.sandStone.blockID);
        		world.setBlock(i + 1, j + 0, k + 7, Block.sandStone.blockID);
        		world.setBlock(i + 1, j + 0, k + 8, Block.sandStone.blockID);
        		world.setBlock(i + 1, j + 0, k + 9, Block.sandStone.blockID);
        		world.setBlock(i + 1, j + 0, k + 10, Block.sandStone.blockID);
        		world.setBlock(i + 1, j + 0, k + 11, Block.sandStone.blockID);
        		world.setBlock(i + 1, j + 0, k + 12, Block.sandStone.blockID);
        		world.setBlock(i + 1, j + 0, k + 13, Block.sandStone.blockID);
        		world.setBlock(i + 1, j + 0, k + 14, Block.sandStone.blockID);
        		world.setBlock(i + 1, j + 0, k + 15, Block.sandStone.blockID);
        		world.setBlock(i + 1, j + 0, k + 16, Block.sandStone.blockID);
        		world.setBlock(i + 1, j + 0, k + 17, Block.sandStone.blockID);
        		world.setBlock(i + 1, j + 0, k + 18, Block.sandStone.blockID);
        		world.setBlock(i + 1, j + 0, k + 19, Block.sandStone.blockID);
        		world.setBlock(i + 1, j + 0, k + 20, Block.sandStone.blockID);
        		world.setBlock(i + 1, j + 0, k + 21, Block.sandStone.blockID);
        		world.setBlock(i + 1, j + 1, k + 1, Block.sandStone.blockID);
        		world.setBlock(i + 1, j + 1, k + 2, Block.sandStone.blockID);
        		world.setBlock(i + 1, j + 1, k + 3, Block.sandStone.blockID);
        		world.setBlock(i + 1, j + 1, k + 4, Block.sandStone.blockID);
        		world.setBlock(i + 1, j + 1, k + 5, Block.sandStone.blockID);
        		world.setBlock(i + 1, j + 1, k + 6, Block.sandStone.blockID);
        		world.setBlock(i + 1, j + 1, k + 7, Block.sandStone.blockID);
        		world.setBlock(i + 1, j + 1, k + 8, Block.sandStone.blockID);
      
        		world.setBlock(i + 1, j + 1, k + 14, Block.sandStone.blockID);
        		world.setBlock(i + 1, j + 1, k + 15, Block.sandStone.blockID);
        		world.setBlock(i + 1, j + 1, k + 16, Block.sandStone.blockID);
        		world.setBlock(i + 1, j + 1, k + 17, Block.sandStone.blockID);
        		world.setBlock(i + 1, j + 1, k + 18, Block.sandStone.blockID);
        		world.setBlock(i + 1, j + 1, k + 19, Block.sandStone.blockID);
        		world.setBlock(i + 1, j + 1, k + 20, Block.sandStone.blockID);
        		world.setBlock(i + 1, j + 1, k + 21, Block.sandStone.blockID);
        		world.setBlock(i + 2, j + 0, k + 1, Block.sandStone.blockID);
        		world.setBlock(i + 2, j + 0, k + 2, Block.sandStone.blockID);
        		world.setBlock(i + 2, j + 0, k + 3, Block.sandStone.blockID);
        		world.setBlock(i + 2, j + 0, k + 4, Block.sandStone.blockID);
        		world.setBlock(i + 2, j + 0, k + 5, Block.sandStone.blockID);
        		world.setBlock(i + 2, j + 0, k + 6, Block.sandStone.blockID);
        		world.setBlock(i + 2, j + 0, k + 7, Block.sandStone.blockID);
        		world.setBlock(i + 2, j + 0, k + 8, Block.sandStone.blockID);
        		world.setBlock(i + 2, j + 0, k + 9, Block.sandStone.blockID);
        		world.setBlock(i + 2, j + 0, k + 10, Block.sandStone.blockID);
        		world.setBlock(i + 2, j + 0, k + 11, Block.sandStone.blockID);
        		world.setBlock(i + 2, j + 0, k + 12, Block.sandStone.blockID);
        		world.setBlock(i + 2, j + 0, k + 13, Block.sandStone.blockID);
        		world.setBlock(i + 2, j + 0, k + 14, Block.sandStone.blockID);
        		world.setBlock(i + 2, j + 0, k + 15, Block.sandStone.blockID);
        		world.setBlock(i + 2, j + 0, k + 16, Block.sandStone.blockID);
        		world.setBlock(i + 2, j + 0, k + 17, Block.sandStone.blockID);
        		world.setBlock(i + 2, j + 0, k + 18, Block.sandStone.blockID);
        		world.setBlock(i + 2, j + 0, k + 19, Block.sandStone.blockID);
        		world.setBlock(i + 2, j + 0, k + 20, Block.sandStone.blockID);
        		world.setBlock(i + 2, j + 0, k + 21, Block.sandStone.blockID);
        		world.setBlock(i + 2, j + 1, k + 1, Block.sandStone.blockID);
        		world.setBlock(i + 2, j + 1, k + 2, Block.sandStone.blockID);
        		world.setBlock(i + 2, j + 1, k + 3, Block.sandStone.blockID);
        		world.setBlock(i + 2, j + 1, k + 4, Block.sandStone.blockID);
        		world.setBlock(i + 2, j + 1, k + 5, Block.sandStone.blockID);
        		world.setBlock(i + 2, j + 1, k + 6, Block.sandStone.blockID);
        		world.setBlock(i + 2, j + 1, k + 7, Block.sandStone.blockID);
        		world.setBlock(i + 2, j + 1, k + 8, Block.sandStone.blockID);
        		world.setBlock(i + 2, j + 1, k + 9, Block.sandStone.blockID);
        		world.setBlock(i + 2, j + 1, k + 10, Block.sandStone.blockID);
        		world.setBlock(i + 2, j + 1, k + 11, Block.sandStone.blockID);
        		world.setBlock(i + 2, j + 1, k + 12, Block.sandStone.blockID);
        		world.setBlock(i + 2, j + 1, k + 13, Block.sandStone.blockID);
        		world.setBlock(i + 2, j + 1, k + 14, Block.sandStone.blockID);
        		world.setBlock(i + 2, j + 1, k + 15, Block.sandStone.blockID);
        		world.setBlock(i + 2, j + 1, k + 16, Block.sandStone.blockID);
        		world.setBlock(i + 2, j + 1, k + 17, Block.sandStone.blockID);
        		world.setBlock(i + 2, j + 1, k + 18, Block.sandStone.blockID);
        		world.setBlock(i + 2, j + 1, k + 19, Block.sandStone.blockID);
        		world.setBlock(i + 2, j + 1, k + 20, Block.sandStone.blockID);
        		world.setBlock(i + 2, j + 1, k + 21, Block.sandStone.blockID);
        		world.setBlock(i + 2, j + 2, k + 2, Block.sandStone.blockID);
        		world.setBlock(i + 2, j + 2, k + 3, Block.sandStone.blockID);
        		world.setBlock(i + 2, j + 2, k + 4, Block.sandStone.blockID);
        		world.setBlock(i + 2, j + 2, k + 5, Block.sandStone.blockID);
        		world.setBlock(i + 2, j + 2, k + 6, Block.sandStone.blockID);
        		world.setBlock(i + 2, j + 2, k + 7, Block.sandStone.blockID);
        		world.setBlock(i + 2, j + 2, k + 8, Block.sandStone.blockID);
        		world.setBlock(i + 2, j + 2, k + 9, Block.sandStone.blockID);
        		world.setBlock(i + 2, j + 2, k + 13, Block.sandStone.blockID);
        		world.setBlock(i + 2, j + 2, k + 14, Block.sandStone.blockID);
        		world.setBlock(i + 2, j + 2, k + 15, Block.sandStone.blockID);
        		world.setBlock(i + 2, j + 2, k + 16, Block.sandStone.blockID);
        		world.setBlock(i + 2, j + 2, k + 17, Block.sandStone.blockID);
        		world.setBlock(i + 2, j + 2, k + 18, Block.sandStone.blockID);
        		world.setBlock(i + 2, j + 2, k + 19, Block.sandStone.blockID);
        		world.setBlock(i + 2, j + 2, k + 20, Block.sandStone.blockID);
        		world.setBlock(i + 2, j + 3, k + 2, Block.sandStone.blockID);
        		world.setBlock(i + 2, j + 3, k + 3, Block.sandStone.blockID);
        		world.setBlock(i + 2, j + 3, k + 4, Block.sandStone.blockID);
        		world.setBlock(i + 2, j + 3, k + 5, Block.sandStone.blockID);
        		world.setBlock(i + 2, j + 3, k + 6, Block.sandStone.blockID);
        		world.setBlock(i + 2, j + 3, k + 7, Block.sandStone.blockID);
        		world.setBlock(i + 2, j + 3, k + 8, Block.sandStone.blockID);
        		world.setBlock(i + 2, j + 3, k + 9, Block.sandStone.blockID);
        		world.setBlock(i + 2, j + 3, k + 13, Block.sandStone.blockID);
        		world.setBlock(i + 2, j + 3, k + 14, Block.sandStone.blockID);
        		world.setBlock(i + 2, j + 3, k + 15, Block.sandStone.blockID);
        		world.setBlock(i + 2, j + 3, k + 16, Block.sandStone.blockID);
        		world.setBlock(i + 2, j + 3, k + 17, Block.sandStone.blockID);
        		world.setBlock(i + 2, j + 3, k + 18, Block.sandStone.blockID);
        		world.setBlock(i + 2, j + 3, k + 19, Block.sandStone.blockID);
        		world.setBlock(i + 2, j + 3, k + 20, Block.sandStone.blockID);
        		world.setBlock(i + 2, j + 4, k + 9, Block.sandStone.blockID);
        		world.setBlock(i + 2, j + 4, k + 13, Block.sandStone.blockID);
        		world.setBlock(i + 3, j + 0, k + 1, Block.sandStone.blockID);
        		world.setBlock(i + 3, j + 0, k + 2, Block.sandStone.blockID);
        		world.setBlock(i + 3, j + 0, k + 9, Block.sandStone.blockID);
        		world.setBlock(i + 3, j + 0, k + 13, Block.sandStone.blockID);
        		world.setBlock(i + 3, j + 0, k + 20, Block.sandStone.blockID);
        		world.setBlock(i + 3, j + 0, k + 21, Block.sandStone.blockID);
        		world.setBlock(i + 3, j + 1, k + 1, Block.sandStone.blockID);
        		world.setBlock(i + 3, j + 1, k + 2, Block.sandStone.blockID);
        	
        		world.setBlock(i + 3, j + 1, k + 9, Block.sandStone.blockID);
        		
        		world.setBlock(i + 3, j + 1, k + 13, Block.sandStone.blockID);
        		world.setBlock(i + 3, j + 1, k + 20, Block.sandStone.blockID);
        		world.setBlock(i + 3, j + 1, k + 21, Block.sandStone.blockID);
        		world.setBlock(i + 3, j + 2, k + 2, Block.sandStone.blockID);
        		world.setBlock(i + 3, j + 2, k + 9, Block.sandStone.blockID);
        		world.setBlock(i + 3, j + 2, k + 13, Block.sandStone.blockID);
        		world.setBlock(i + 3, j + 2, k + 20, Block.sandStone.blockID);
        		world.setBlock(i + 3, j + 3, k + 2, Block.sandStone.blockID);
        		world.setBlock(i + 3, j + 3, k + 9, Block.sandStone.blockID);
        		world.setBlock(i + 3, j + 3, k + 13, Block.sandStone.blockID);
        		world.setBlock(i + 3, j + 3, k + 20, Block.sandStone.blockID);
        		world.setBlock(i + 3, j + 4, k + 3, Block.sandStone.blockID);
        		world.setBlock(i + 3, j + 4, k + 4, Block.sandStone.blockID);
        		world.setBlock(i + 3, j + 4, k + 5, Block.sandStone.blockID);
        		world.setBlock(i + 3, j + 4, k + 6, Block.sandStone.blockID);
        		world.setBlock(i + 3, j + 4, k + 7, Block.sandStone.blockID);
        		world.setBlock(i + 3, j + 4, k + 8, Block.sandStone.blockID);
        		world.setBlock(i + 3, j + 4, k + 9, Block.sandStone.blockID);
        		world.setBlock(i + 3, j + 4, k + 13, Block.sandStone.blockID);
        		world.setBlock(i + 3, j + 4, k + 14, Block.sandStone.blockID);
        		world.setBlock(i + 3, j + 4, k + 15, Block.sandStone.blockID);
        		world.setBlock(i + 3, j + 4, k + 16, Block.sandStone.blockID);
        		world.setBlock(i + 3, j + 4, k + 17, Block.sandStone.blockID);
        		world.setBlock(i + 3, j + 4, k + 18, Block.sandStone.blockID);
        		world.setBlock(i + 3, j + 4, k + 19, Block.sandStone.blockID);
        		world.setBlock(i + 3, j + 5, k + 3, Block.sandStone.blockID);
        		world.setBlock(i + 3, j + 5, k + 4, Block.sandStone.blockID);
        		world.setBlock(i + 3, j + 5, k + 5, Block.sandStone.blockID);
        		world.setBlock(i + 3, j + 5, k + 6, Block.sandStone.blockID);
        		world.setBlock(i + 3, j + 5, k + 7, Block.sandStone.blockID);
        		world.setBlock(i + 3, j + 5, k + 8, Block.sandStone.blockID);
        		world.setBlock(i + 3, j + 5, k + 9, Block.sandStone.blockID);
        		world.setBlock(i + 3, j + 5, k + 10, Block.sandStone.blockID);
        		world.setBlock(i + 3, j + 5, k + 11, Block.sandStone.blockID);
        		world.setBlock(i + 3, j + 5, k + 12, Block.sandStone.blockID);
        		world.setBlock(i + 3, j + 5, k + 13, Block.sandStone.blockID);
        		world.setBlock(i + 3, j + 5, k + 14, Block.sandStone.blockID);
        		world.setBlock(i + 3, j + 5, k + 15, Block.sandStone.blockID);
        		world.setBlock(i + 3, j + 5, k + 16, Block.sandStone.blockID);
        		world.setBlock(i + 3, j + 5, k + 17, Block.sandStone.blockID);
        		world.setBlock(i + 3, j + 5, k + 18, Block.sandStone.blockID);
        		world.setBlock(i + 3, j + 5, k + 19, Block.sandStone.blockID);
        		world.setBlock(i + 4, j + 0, k + 1, Block.sandStone.blockID);
        		world.setBlock(i + 4, j + 0, k + 2, Block.sandStone.blockID);
        		world.setBlock(i + 4, j + 0, k + 20, Block.sandStone.blockID);
        		world.setBlock(i + 4, j + 0, k + 21, Block.sandStone.blockID);
        		world.setBlock(i + 4, j + 1, k + 1, Block.sandStone.blockID);
        		world.setBlock(i + 4, j + 1, k + 2, Block.sandStone.blockID);
        		world.setBlock(i + 4, j + 1, k + 20, Block.sandStone.blockID);
        		world.setBlock(i + 4, j + 1, k + 21, Block.sandStone.blockID);
        		world.setBlock(i + 4, j + 2, k + 2, Block.sandStone.blockID);
        		world.setBlock(i + 4, j + 2, k + 20, Block.sandStone.blockID);
        		world.setBlock(i + 4, j + 3, k + 2, Block.sandStone.blockID);
        		world.setBlock(i + 4, j + 3, k + 20, Block.sandStone.blockID);
        		world.setBlock(i + 4, j + 4, k + 3, Block.sandStone.blockID);
        		world.setBlock(i + 4, j + 4, k + 19, Block.sandStone.blockID);
        		world.setBlock(i + 4, j + 5, k + 3, Block.sandStone.blockID);
        		world.setBlock(i + 4, j + 5, k + 19, Block.sandStone.blockID);
        		world.setBlock(i + 4, j + 6, k + 4, Block.sandStone.blockID);
        		world.setBlock(i + 4, j + 6, k + 5, Block.sandStone.blockID);
        		world.setBlock(i + 4, j + 6, k + 6, Block.sandStone.blockID);
        		world.setBlock(i + 4, j + 6, k + 7, Block.sandStone.blockID);
        		world.setBlock(i + 4, j + 6, k + 8, Block.sandStone.blockID);
        		world.setBlock(i + 4, j + 6, k + 9, Block.sandStone.blockID);
        		world.setBlock(i + 4, j + 6, k + 10, Block.sandStone.blockID);
        		world.setBlock(i + 4, j + 6, k + 11, Block.sandStone.blockID);
        		world.setBlock(i + 4, j + 6, k + 12, Block.sandStone.blockID);
        		world.setBlock(i + 4, j + 6, k + 13, Block.sandStone.blockID);
        		world.setBlock(i + 4, j + 6, k + 14, Block.sandStone.blockID);
        		world.setBlock(i + 4, j + 6, k + 15, Block.sandStone.blockID);
        		world.setBlock(i + 4, j + 6, k + 16, Block.sandStone.blockID);
        		world.setBlock(i + 4, j + 6, k + 17, Block.sandStone.blockID);
        		world.setBlock(i + 4, j + 6, k + 18, Block.sandStone.blockID);
        		world.setBlock(i + 4, j + 7, k + 4, Block.sandStone.blockID);
        		world.setBlock(i + 4, j + 7, k + 5, Block.sandStone.blockID);
        		world.setBlock(i + 4, j + 7, k + 6, Block.sandStone.blockID);
        		world.setBlock(i + 4, j + 7, k + 7, Block.sandStone.blockID);
        		world.setBlock(i + 4, j + 7, k + 8, Block.sandStone.blockID);
        		world.setBlock(i + 4, j + 7, k + 9, Block.sandStone.blockID);
        		world.setBlock(i + 4, j + 7, k + 10, Block.sandStone.blockID);
        		world.setBlock(i + 4, j + 7, k + 11, Block.sandStone.blockID);
        		world.setBlock(i + 4, j + 7, k + 12, Block.sandStone.blockID);
        		world.setBlock(i + 4, j + 7, k + 13, Block.sandStone.blockID);
        		world.setBlock(i + 4, j + 7, k + 14, Block.sandStone.blockID);
        		world.setBlock(i + 4, j + 7, k + 15, Block.sandStone.blockID);
        		world.setBlock(i + 4, j + 7, k + 16, Block.sandStone.blockID);
        		world.setBlock(i + 4, j + 7, k + 17, Block.sandStone.blockID);
        		world.setBlock(i + 4, j + 7, k + 18, Block.sandStone.blockID);
        		world.setBlock(i + 5, j + 0, k + 1, Block.sandStone.blockID);
        		world.setBlock(i + 5, j + 0, k + 2, Block.sandStone.blockID);
        		world.setBlock(i + 5, j + 0, k + 20, Block.sandStone.blockID);
        		world.setBlock(i + 5, j + 0, k + 21, Block.sandStone.blockID);
        		world.setBlock(i + 5, j + 1, k + 1, Block.sandStone.blockID);
        		world.setBlock(i + 5, j + 1, k + 2, Block.sandStone.blockID);
        		
        		world.setBlock(i + 5, j + 1, k + 20, Block.sandStone.blockID);
        		world.setBlock(i + 5, j + 1, k + 21, Block.sandStone.blockID);
        		world.setBlock(i + 5, j + 2, k + 2, Block.sandStone.blockID);
        		world.setBlock(i + 5, j + 2, k + 20, Block.sandStone.blockID);
        		world.setBlock(i + 5, j + 3, k + 2, Block.sandStone.blockID);
        		world.setBlock(i + 5, j + 3, k + 20, Block.sandStone.blockID);
        		world.setBlock(i + 5, j + 4, k + 3, Block.sandStone.blockID);
        		world.setBlock(i + 5, j + 4, k + 19, Block.sandStone.blockID);
        		world.setBlock(i + 5, j + 5, k + 3, Block.sandStone.blockID);
        		world.setBlock(i + 5, j + 5, k + 19, Block.sandStone.blockID);
        		world.setBlock(i + 5, j + 6, k + 4, Block.sandStone.blockID);
        		world.setBlock(i + 5, j + 6, k + 18, Block.sandStone.blockID);
        		world.setBlock(i + 5, j + 7, k + 4, Block.sandStone.blockID);
        		world.setBlock(i + 5, j + 7, k + 18, Block.sandStone.blockID);
        		world.setBlock(i + 5, j + 8, k + 5, Block.sandStone.blockID);
        		world.setBlock(i + 5, j + 8, k + 6, Block.sandStone.blockID);
        		world.setBlock(i + 5, j + 8, k + 7, Block.sandStone.blockID);
        		world.setBlock(i + 5, j + 8, k + 8, Block.sandStone.blockID);
        		world.setBlock(i + 5, j + 8, k + 9, Block.sandStone.blockID);
        		world.setBlock(i + 5, j + 8, k + 10, Block.sandStone.blockID);
        		world.setBlock(i + 5, j + 8, k + 11, Block.sandStone.blockID);
        		world.setBlock(i + 5, j + 8, k + 12, Block.sandStone.blockID);
        		world.setBlock(i + 5, j + 8, k + 13, Block.sandStone.blockID);
        		world.setBlock(i + 5, j + 8, k + 14, Block.sandStone.blockID);
        		world.setBlock(i + 5, j + 8, k + 15, Block.sandStone.blockID);
        		world.setBlock(i + 5, j + 8, k + 16, Block.sandStone.blockID);
        		world.setBlock(i + 5, j + 8, k + 17, Block.sandStone.blockID);
        		world.setBlock(i + 5, j + 9, k + 5, Block.sandStone.blockID);
        		world.setBlock(i + 5, j + 9, k + 6, Block.sandStone.blockID);
        		world.setBlock(i + 5, j + 9, k + 7, Block.sandStone.blockID);
        		world.setBlock(i + 5, j + 9, k + 8, Block.sandStone.blockID);
        		world.setBlock(i + 5, j + 9, k + 9, Block.sandStone.blockID);
        		world.setBlock(i + 5, j + 9, k + 10, Block.sandStone.blockID);
        		world.setBlock(i + 5, j + 9, k + 11, Block.sandStone.blockID);
        		world.setBlock(i + 5, j + 9, k + 12, Block.sandStone.blockID);
        		world.setBlock(i + 5, j + 9, k + 13, Block.sandStone.blockID);
        		world.setBlock(i + 5, j + 9, k + 14, Block.sandStone.blockID);
        		world.setBlock(i + 5, j + 9, k + 15, Block.sandStone.blockID);
        		world.setBlock(i + 5, j + 9, k + 16, Block.sandStone.blockID);
        		world.setBlock(i + 5, j + 9, k + 17, Block.sandStone.blockID);
        		world.setBlock(i + 6, j + 0, k + 1, Block.sandStone.blockID);
        		world.setBlock(i + 6, j + 0, k + 2, Block.sandStone.blockID);
        		world.setBlock(i + 6, j + 0, k + 20, Block.sandStone.blockID);
        		world.setBlock(i + 6, j + 0, k + 21, Block.sandStone.blockID);
        		world.setBlock(i + 6, j + 1, k + 1, Block.sandStone.blockID);
        		world.setBlock(i + 6, j + 1, k + 2, Block.sandStone.blockID);
        	
        		world.setBlock(i + 6, j + 1, k + 20, Block.sandStone.blockID);
        		world.setBlock(i + 6, j + 1, k + 21, Block.sandStone.blockID);
        		world.setBlock(i + 6, j + 2, k + 2, Block.sandStone.blockID);
        		world.setBlock(i + 6, j + 2, k + 20, Block.sandStone.blockID);
        		world.setBlock(i + 6, j + 3, k + 2, Block.sandStone.blockID);
        		world.setBlock(i + 6, j + 3, k + 20, Block.sandStone.blockID);
        		world.setBlock(i + 6, j + 4, k + 3, Block.sandStone.blockID);
        		world.setBlock(i + 6, j + 4, k + 19, Block.sandStone.blockID);
        		world.setBlock(i + 6, j + 5, k + 3, Block.sandStone.blockID);
        		world.setBlock(i + 6, j + 5, k + 19, Block.sandStone.blockID);
        		world.setBlock(i + 6, j + 6, k + 4, Block.sandStone.blockID);
        		world.setBlock(i + 6, j + 6, k + 18, Block.sandStone.blockID);
        		world.setBlock(i + 6, j + 7, k + 4, Block.sandStone.blockID);
        		world.setBlock(i + 6, j + 7, k + 18, Block.sandStone.blockID);
        		world.setBlock(i + 6, j + 8, k + 5, Block.sandStone.blockID);
        		world.setBlock(i + 6, j + 8, k + 17, Block.sandStone.blockID);
        		world.setBlock(i + 6, j + 9, k + 5, Block.sandStone.blockID);
        		world.setBlock(i + 6, j + 9, k + 17, Block.sandStone.blockID);
        		world.setBlock(i + 6, j + 10, k + 6, Block.sandStone.blockID);
        		world.setBlock(i + 6, j + 10, k + 7, Block.sandStone.blockID);
        		world.setBlock(i + 6, j + 10, k + 8, Block.sandStone.blockID);
        		world.setBlock(i + 6, j + 10, k + 9, Block.sandStone.blockID);
        		world.setBlock(i + 6, j + 10, k + 10, Block.sandStone.blockID);
        		world.setBlock(i + 6, j + 10, k + 11, Block.sandStone.blockID);
        		world.setBlock(i + 6, j + 10, k + 12, Block.sandStone.blockID);
        		world.setBlock(i + 6, j + 10, k + 13, Block.sandStone.blockID);
        		world.setBlock(i + 6, j + 10, k + 14, Block.sandStone.blockID);
        		world.setBlock(i + 6, j + 10, k + 15, Block.sandStone.blockID);
        		world.setBlock(i + 6, j + 10, k + 16, Block.sandStone.blockID);
        		world.setBlock(i + 6, j + 11, k + 6, Block.sandStone.blockID);
        		world.setBlock(i + 6, j + 11, k + 7, Block.sandStone.blockID);
        		world.setBlock(i + 6, j + 11, k + 8, Block.sandStone.blockID);
        		world.setBlock(i + 6, j + 11, k + 9, Block.sandStone.blockID);
        		world.setBlock(i + 6, j + 11, k + 10, Block.sandStone.blockID);
        		world.setBlock(i + 6, j + 11, k + 11, Block.sandStone.blockID);
        		world.setBlock(i + 6, j + 11, k + 12, Block.sandStone.blockID);
        		world.setBlock(i + 6, j + 11, k + 13, Block.sandStone.blockID);
        		world.setBlock(i + 6, j + 11, k + 14, Block.sandStone.blockID);
        		world.setBlock(i + 6, j + 11, k + 15, Block.sandStone.blockID);
        		world.setBlock(i + 6, j + 11, k + 16, Block.sandStone.blockID);
        		world.setBlock(i + 7, j + 0, k + 1, Block.sandStone.blockID);
        		world.setBlock(i + 7, j + 0, k + 2, Block.sandStone.blockID);
        		world.setBlock(i + 7, j + 0, k + 20, Block.sandStone.blockID);
        		world.setBlock(i + 7, j + 0, k + 21, Block.sandStone.blockID);
        		world.setBlock(i + 7, j + 1, k + 1, Block.sandStone.blockID);
        		world.setBlock(i + 7, j + 1, k + 2, Block.sandStone.blockID);
        	
        		world.setBlock(i + 7, j + 1, k + 20, Block.sandStone.blockID);
        		world.setBlock(i + 7, j + 1, k + 21, Block.sandStone.blockID);
        		world.setBlock(i + 7, j + 2, k + 2, Block.sandStone.blockID);
        		world.setBlock(i + 7, j + 2, k + 20, Block.sandStone.blockID);
        		world.setBlock(i + 7, j + 3, k + 2, Block.sandStone.blockID);
        		world.setBlock(i + 7, j + 3, k + 20, Block.sandStone.blockID);
        		world.setBlock(i + 7, j + 4, k + 3, Block.sandStone.blockID);
        		world.setBlock(i + 7, j + 4, k + 19, Block.sandStone.blockID);
        		world.setBlock(i + 7, j + 5, k + 3, Block.sandStone.blockID);
        		world.setBlock(i + 7, j + 5, k + 19, Block.sandStone.blockID);
        		world.setBlock(i + 7, j + 6, k + 4, Block.sandStone.blockID);
        		world.setBlock(i + 7, j + 6, k + 18, Block.sandStone.blockID);
        		world.setBlock(i + 7, j + 7, k + 4, Block.sandStone.blockID);
        		world.setBlock(i + 7, j + 7, k + 18, Block.sandStone.blockID);
        		world.setBlock(i + 7, j + 8, k + 5, Block.sandStone.blockID);
        		world.setBlock(i + 7, j + 8, k + 17, Block.sandStone.blockID);
        		world.setBlock(i + 7, j + 9, k + 5, Block.sandStone.blockID);
        		world.setBlock(i + 7, j + 9, k + 17, Block.sandStone.blockID);
        		world.setBlock(i + 7, j + 10, k + 6, Block.sandStone.blockID);
        		world.setBlock(i + 7, j + 10, k + 16, Block.sandStone.blockID);
        		world.setBlock(i + 7, j + 11, k + 6, Block.sandStone.blockID);
        		world.setBlock(i + 7, j + 11, k + 16, Block.sandStone.blockID);
        		world.setBlock(i + 7, j + 12, k + 7, Block.sandStone.blockID);
        		world.setBlock(i + 7, j + 12, k + 8, Block.sandStone.blockID);
        		world.setBlock(i + 7, j + 12, k + 9, Block.sandStone.blockID);
        		world.setBlock(i + 7, j + 12, k + 10, Block.sandStone.blockID);
        		world.setBlock(i + 7, j + 12, k + 11, Block.sandStone.blockID);
        		world.setBlock(i + 7, j + 12, k + 12, Block.sandStone.blockID);
        		world.setBlock(i + 7, j + 12, k + 13, Block.sandStone.blockID);
        		world.setBlock(i + 7, j + 12, k + 14, Block.sandStone.blockID);
        		world.setBlock(i + 7, j + 12, k + 15, Block.sandStone.blockID);
        		world.setBlock(i + 7, j + 13, k + 7, Block.sandStone.blockID);
        		world.setBlock(i + 7, j + 13, k + 8, Block.sandStone.blockID);
        		world.setBlock(i + 7, j + 13, k + 9, Block.sandStone.blockID);
        		world.setBlock(i + 7, j + 13, k + 10, Block.sandStone.blockID);
        		world.setBlock(i + 7, j + 13, k + 11, Block.sandStone.blockID);
        		world.setBlock(i + 7, j + 13, k + 12, Block.sandStone.blockID);
        		world.setBlock(i + 7, j + 13, k + 13, Block.sandStone.blockID);
        		world.setBlock(i + 7, j + 13, k + 14, Block.sandStone.blockID);
        		world.setBlock(i + 7, j + 13, k + 15, Block.sandStone.blockID);
        		world.setBlock(i + 8, j + 0, k + 1, Block.sandStone.blockID);
        		world.setBlock(i + 8, j + 0, k + 2, Block.sandStone.blockID);
        		world.setBlock(i + 8, j + 0, k + 20, Block.sandStone.blockID);
        		world.setBlock(i + 8, j + 0, k + 21, Block.sandStone.blockID);
        		world.setBlock(i + 8, j + 1, k + 1, Block.sandStone.blockID);
        		world.setBlock(i + 8, j + 1, k + 2, Block.sandStone.blockID);
        	
        		world.setBlock(i + 8, j + 1, k + 20, Block.sandStone.blockID);
        		world.setBlock(i + 8, j + 1, k + 21, Block.sandStone.blockID);
        		world.setBlock(i + 8, j + 2, k + 2, Block.sandStone.blockID);
        		world.setBlock(i + 8, j + 2, k + 20, Block.sandStone.blockID);
        		world.setBlock(i + 8, j + 3, k + 2, Block.sandStone.blockID);
        		world.setBlock(i + 8, j + 3, k + 20, Block.sandStone.blockID);
        		world.setBlock(i + 8, j + 4, k + 3, Block.sandStone.blockID);
        		world.setBlock(i + 8, j + 4, k + 19, Block.sandStone.blockID);
        		world.setBlock(i + 8, j + 5, k + 3, Block.sandStone.blockID);
        		world.setBlock(i + 8, j + 5, k + 19, Block.sandStone.blockID);
        		world.setBlock(i + 8, j + 6, k + 4, Block.sandStone.blockID);
        		world.setBlock(i + 8, j + 6, k + 18, Block.sandStone.blockID);
        		world.setBlock(i + 8, j + 7, k + 4, Block.sandStone.blockID);
        		world.setBlock(i + 8, j + 7, k + 18, Block.sandStone.blockID);
        		world.setBlock(i + 8, j + 8, k + 5, Block.sandStone.blockID);
        		world.setBlock(i + 8, j + 8, k + 17, Block.sandStone.blockID);
        		world.setBlock(i + 8, j + 9, k + 5, Block.sandStone.blockID);
        		world.setBlock(i + 8, j + 9, k + 17, Block.sandStone.blockID);
        		world.setBlock(i + 8, j + 10, k + 6, Block.sandStone.blockID);
        		world.setBlock(i + 8, j + 10, k + 16, Block.sandStone.blockID);
        		world.setBlock(i + 8, j + 11, k + 6, Block.sandStone.blockID);
        		world.setBlock(i + 8, j + 11, k + 16, Block.sandStone.blockID);
        		world.setBlock(i + 8, j + 12, k + 7, Block.sandStone.blockID);
        		world.setBlock(i + 8, j + 12, k + 15, Block.sandStone.blockID);
        		world.setBlock(i + 8, j + 13, k + 7, Block.sandStone.blockID);
        		world.setBlock(i + 8, j + 13, k + 15, Block.sandStone.blockID);
        		world.setBlock(i + 8, j + 14, k + 8, Block.sandStone.blockID);
        		world.setBlock(i + 8, j + 14, k + 9, Block.sandStone.blockID);
        		world.setBlock(i + 8, j + 14, k + 10, Block.sandStone.blockID);
        		world.setBlock(i + 8, j + 14, k + 11, Block.sandStone.blockID);
        		world.setBlock(i + 8, j + 14, k + 12, Block.sandStone.blockID);
        		world.setBlock(i + 8, j + 14, k + 13, Block.sandStone.blockID);
        		world.setBlock(i + 8, j + 14, k + 14, Block.sandStone.blockID);
        		world.setBlock(i + 8, j + 15, k + 8, Block.sandStone.blockID);
        		world.setBlock(i + 8, j + 15, k + 9, Block.sandStone.blockID);
        		world.setBlock(i + 8, j + 15, k + 10, Block.sandStone.blockID);
        		world.setBlock(i + 8, j + 15, k + 11, Block.sandStone.blockID);
        		world.setBlock(i + 8, j + 15, k + 12, Block.sandStone.blockID);
        		world.setBlock(i + 8, j + 15, k + 13, Block.sandStone.blockID);
        		world.setBlock(i + 8, j + 15, k + 14, Block.sandStone.blockID);
        	
        		world.setBlock(i + 9, j + 0, k + 1, Block.sandStone.blockID);
        		world.setBlock(i + 9, j + 0, k + 2, Block.sandStone.blockID);
        		world.setBlock(i + 9, j + 0, k + 3, Block.sandStone.blockID);
        	
        		world.setBlock(i + 9, j + 0, k + 19, Block.sandStone.blockID);
        		world.setBlock(i + 9, j + 0, k + 20, Block.sandStone.blockID);
        		world.setBlock(i + 9, j + 0, k + 21, Block.sandStone.blockID);
        		//(i + 9, j + 0, k + 22, -128, 1);
        		//(i + 9, j + 1, k + 1, -128, 1);
        		world.setBlock(i + 9, j + 1, k + 2, Block.sandStone.blockID);
        		world.setBlock(i + 9, j + 1, k + 3, Block.sandStone.blockID);
        		//(i + 9, j + 1, k + 5, Block.stoneSingleSlab.blockID, 9);
        		//(i + 9, j + 1, k + 6, Block.stoneSingleSlab.blockID, 9);
        		//(i + 9, j + 1, k + 9, Block.sandStone.blockID, 2);
        		//(i + 9, j + 1, k + 10, Block.stoneSingleSlab.blockID, 8);
        		//(i + 9, j + 1, k + 11, Block.stoneSingleSlab.blockID, 8);
        		//(i + 9, j + 1, k + 12, Block.stoneSingleSlab.blockID, 8);
        		//(i + 9, j + 1, k + 13, Block.sandStone.blockID, 2);
        		//(i + 9, j + 1, k + 16, Block.stoneSingleSlab.blockID, 9);
        		//(i + 9, j + 1, k + 17, Block.stoneSingleSlab.blockID, 9);
        		world.setBlock(i + 9, j + 1, k + 19, Block.sandStone.blockID);
        		world.setBlock(i + 9, j + 1, k + 20, Block.sandStone.blockID);
        		//(i + 9, j + 1, k + 21, -128, 1);
        		world.setBlock(i + 9, j + 2, k + 2, Block.sandStone.blockID);
        		world.setBlock(i + 9, j + 2, k + 3, Block.sandStone.blockID);
        		//(i + 9, j + 2, k + 9, Block.sandStone.blockID, 2);
        		//(i + 9, j + 2, k + 13, Block.sandStone.blockID, 2);
        		world.setBlock(i + 9, j + 2, k + 19, Block.sandStone.blockID);
        		world.setBlock(i + 9, j + 2, k + 20, Block.sandStone.blockID);
        		world.setBlock(i + 9, j + 3, k + 2, Block.sandStone.blockID);
        		world.setBlock(i + 9, j + 3, k + 3, Block.sandStone.blockID);
        		//(i + 9, j + 3, k + 9, Block.sandStone.blockID, 1);
        		//(i + 9, j + 3, k + 13, Block.sandStone.blockID, 1);
        		world.setBlock(i + 9, j + 3, k + 19, Block.sandStone.blockID);
        		world.setBlock(i + 9, j + 3, k + 20, Block.sandStone.blockID);
        		world.setBlock(i + 9, j + 4, k + 2, Block.sandStone.blockID);
        		world.setBlock(i + 9, j + 4, k + 3, Block.sandStone.blockID);
        		world.setBlock(i + 9, j + 4, k + 19, Block.sandStone.blockID);
        		world.setBlock(i + 9, j + 4, k + 20, Block.sandStone.blockID);
        		world.setBlock(i + 9, j + 5, k + 3, Block.sandStone.blockID);
        		world.setBlock(i + 9, j + 5, k + 19, Block.sandStone.blockID);
        		world.setBlock(i + 9, j + 6, k + 4, Block.sandStone.blockID);
        		world.setBlock(i + 9, j + 6, k + 18, Block.sandStone.blockID);
        		world.setBlock(i + 9, j + 7, k + 4, Block.sandStone.blockID);
        		world.setBlock(i + 9, j + 7, k + 18, Block.sandStone.blockID);
        		world.setBlock(i + 9, j + 8, k + 5, Block.sandStone.blockID);
        		world.setBlock(i + 9, j + 8, k + 17, Block.sandStone.blockID);
        		world.setBlock(i + 9, j + 9, k + 5, Block.sandStone.blockID);
        		world.setBlock(i + 9, j + 9, k + 17, Block.sandStone.blockID);
        		world.setBlock(i + 9, j + 10, k + 6, Block.sandStone.blockID);
        		world.setBlock(i + 9, j + 10, k + 16, Block.sandStone.blockID);
        		world.setBlock(i + 9, j + 11, k + 6, Block.sandStone.blockID);
        		world.setBlock(i + 9, j + 11, k + 16, Block.sandStone.blockID);
        		world.setBlock(i + 9, j + 12, k + 7, Block.sandStone.blockID);
        		world.setBlock(i + 9, j + 12, k + 15, Block.sandStone.blockID);
        		world.setBlock(i + 9, j + 13, k + 7, Block.sandStone.blockID);
        		world.setBlock(i + 9, j + 13, k + 15, Block.sandStone.blockID);
        		world.setBlock(i + 9, j + 14, k + 8, Block.sandStone.blockID);
        		world.setBlock(i + 9, j + 14, k + 14, Block.sandStone.blockID);
        		world.setBlock(i + 9, j + 15, k + 8, Block.sandStone.blockID);
        		world.setBlock(i + 9, j + 15, k + 14, Block.sandStone.blockID);
        		world.setBlock(i + 9, j + 16, k + 9, Block.sandStone.blockID);
        		world.setBlock(i + 9, j + 16, k + 10, Block.sandStone.blockID);
        		world.setBlock(i + 9, j + 16, k + 11, Block.sandStone.blockID);
        		world.setBlock(i + 9, j + 16, k + 12, Block.sandStone.blockID);
        		world.setBlock(i + 9, j + 16, k + 13, Block.sandStone.blockID);
        		world.setBlock(i + 9, j + 17, k + 9, Block.sandStone.blockID);
        		world.setBlock(i + 9, j + 17, k + 10, Block.sandStone.blockID);
        		world.setBlock(i + 9, j + 17, k + 11, Block.sandStone.blockID);
        		world.setBlock(i + 9, j + 17, k + 12, Block.sandStone.blockID);
        		world.setBlock(i + 9, j + 17, k + 13, Block.sandStone.blockID);
        		//(i + 10, j + 0, k + 0, -128, 2);
        		world.setBlock(i + 10, j + 0, k + 1, Block.sandStone.blockID);
        		world.setBlock(i + 10, j + 0, k + 2, Block.sandStone.blockID);
        		world.setBlock(i + 10, j + 0, k + 20, Block.sandStone.blockID);
        		world.setBlock(i + 10, j + 0, k + 21, Block.sandStone.blockID);
        		//(i + 10, j + 0, k + 22, -128, 3);
        		//(i + 10, j + 1, k + 1, -128, 2);
        		world.setBlock(i + 10, j + 1, k + 2, Block.sandStone.blockID);
        		//(i + 10, j + 1, k + 3, -128, 7);
        		//(i + 10, j + 1, k + 4, Block.stoneSingleSlab.blockID, 9);
        		//(i + 10, j + 1, k + 5, Block.stoneSingleSlab.blockID, 9);
        		//(i + 10, j + 1, k + 6, Block.stoneSingleSlab.blockID, 9);
        		//(i + 10, j + 1, k + 7, Block.stoneSingleSlab.blockID, 9);
        		//(i + 10, j + 1, k + 8, Block.stoneSingleSlab.blockID, 9);
        		//(i + 10, j + 1, k + 9, Block.stoneSingleSlab.blockID, 8);
        		//(i + 10, j + 1, k + 10, Block.stoneSingleSlab.blockID, 8);
        		//(i + 10, j + 1, k + 11, Block.stoneSingleSlab.blockID, 8);
        		//(i + 10, j + 1, k + 12, Block.stoneSingleSlab.blockID, 8);
        		//(i + 10, j + 1, k + 13, Block.stoneSingleSlab.blockID, 8);
        		//(i + 10, j + 1, k + 14, Block.stoneSingleSlab.blockID, 9);
        		//(i + 10, j + 1, k + 15, Block.stoneSingleSlab.blockID, 9);
        		//(i + 10, j + 1, k + 16, Block.stoneSingleSlab.blockID, 9);
        		//(i + 10, j + 1, k + 17, Block.stoneSingleSlab.blockID, 9);
        		//(i + 10, j + 1, k + 18, Block.stoneSingleSlab.blockID, 9);
        		//(i + 10, j + 1, k + 19, -128, 6);
        		world.setBlock(i + 10, j + 1, k + 20, Block.sandStone.blockID);
        		//(i + 10, j + 1, k + 21, -128, 3);
        		//(i + 10, j + 4, k + 2, -128, 5);
        		//(i + 10, j + 4, k + 3, -128, 5);
        		//(i + 10, j + 4, k + 19, -128, 5);
        		//(i + 10, j + 4, k + 20, -128, 5);
        		world.setBlock(i + 10, j + 5, k + 3, Block.sandStone.blockID);
        		world.setBlock(i + 10, j + 5, k + 19, Block.sandStone.blockID);
        		world.setBlock(i + 10, j + 6, k + 4, Block.sandStone.blockID);
        		world.setBlock(i + 10, j + 6, k + 18, Block.sandStone.blockID);
        		world.setBlock(i + 10, j + 7, k + 4, Block.sandStone.blockID);
        		world.setBlock(i + 10, j + 7, k + 18, Block.sandStone.blockID);
        		world.setBlock(i + 10, j + 8, k + 5, Block.sandStone.blockID);
        		world.setBlock(i + 10, j + 8, k + 17, Block.sandStone.blockID);
        		world.setBlock(i + 10, j + 9, k + 5, Block.sandStone.blockID);
        		world.setBlock(i + 10, j + 9, k + 17, Block.sandStone.blockID);
        		world.setBlock(i + 10, j + 10, k + 6, Block.sandStone.blockID);
        		world.setBlock(i + 10, j + 10, k + 16, Block.sandStone.blockID);
        		world.setBlock(i + 10, j + 11, k + 6, Block.sandStone.blockID);
        		world.setBlock(i + 10, j + 11, k + 16, Block.sandStone.blockID);
        		world.setBlock(i + 10, j + 12, k + 7, Block.sandStone.blockID);
        		world.setBlock(i + 10, j + 12, k + 15, Block.sandStone.blockID);
        		world.setBlock(i + 10, j + 13, k + 7, Block.sandStone.blockID);
        		world.setBlock(i + 10, j + 13, k + 15, Block.sandStone.blockID);
        		world.setBlock(i + 10, j + 14, k + 8, Block.sandStone.blockID);
        		world.setBlock(i + 10, j + 14, k + 14, Block.sandStone.blockID);
        		world.setBlock(i + 10, j + 15, k + 8, Block.sandStone.blockID);
        		world.setBlock(i + 10, j + 15, k + 14, Block.sandStone.blockID);
        		world.setBlock(i + 10, j + 16, k + 9, Block.sandStone.blockID);
        		world.setBlock(i + 10, j + 16, k + 10, Block.glowStone.blockID);
        		world.setBlock(i + 10, j + 16, k + 11, Block.glowStone.blockID);
        		world.setBlock(i + 10, j + 16, k + 12, Block.glowStone.blockID);
        		world.setBlock(i + 10, j + 16, k + 13, Block.sandStone.blockID);
        		world.setBlock(i + 10, j + 17, k + 9, Block.sandStone.blockID);
        		world.setBlock(i + 10, j + 17, k + 13, Block.sandStone.blockID);
        		world.setBlock(i + 10, j + 18, k + 10, Block.sandStone.blockID);
        		world.setBlock(i + 10, j + 18, k + 11, Block.sandStone.blockID);
        		world.setBlock(i + 10, j + 18, k + 12, Block.sandStone.blockID);
        		world.setBlock(i + 10, j + 19, k + 10, Block.sandStone.blockID);
        		world.setBlock(i + 10, j + 19, k + 11, Block.sandStone.blockID);
        		world.setBlock(i + 10, j + 19, k + 12, Block.sandStone.blockID);
        		//(i + 11, j + 0, k + 0, -128, 2);
        		world.setBlock(i + 11, j + 0, k + 1, Block.sandStone.blockID);
        		world.setBlock(i + 11, j + 0, k + 2, Block.sandStone.blockID);
        		world.setBlock(i + 11, j + 0, k + 20, Block.sandStone.blockID);
        		world.setBlock(i + 11, j + 0, k + 21, Block.sandStone.blockID);
        		//(i + 11, j + 0, k + 22, -128, 3);
        		//(i + 11, j + 1, k + 1, -128, 2);
        		world.setBlock(i + 11, j + 1, k + 2, Block.sandStone.blockID);
        		//(i + 11, j + 1, k + 3, -128, 7);
        		//(i + 11, j + 1, k + 4, Block.stoneSingleSlab.blockID, 9);
        		//(i + 11, j + 1, k + 5, Block.stoneSingleSlab.blockID, 9);
        		//(i + 11, j + 1, k + 6, Block.stoneSingleSlab.blockID, 9);
        		//(i + 11, j + 1, k + 7, Block.stoneSingleSlab.blockID, 9);
        		//(i + 11, j + 1, k + 8, Block.stoneSingleSlab.blockID, 9);
        		//(i + 11, j + 1, k + 9, Block.stoneSingleSlab.blockID, 8);
        		//(i + 11, j + 1, k + 10, Block.stoneSingleSlab.blockID, 8);
        		//(i + 11, j + 1, k + 11, Block.stoneSingleSlab.blockID, 8);
        		//(i + 11, j + 1, k + 12, Block.stoneSingleSlab.blockID, 8);
        		//(i + 11, j + 1, k + 13, Block.stoneSingleSlab.blockID, 8);
        		//(i + 11, j + 1, k + 14, Block.stoneSingleSlab.blockID, 9);
        		//(i + 11, j + 1, k + 15, Block.stoneSingleSlab.blockID, 9);
        		//(i + 11, j + 1, k + 16, Block.stoneSingleSlab.blockID, 9);
        		//(i + 11, j + 1, k + 17, Block.stoneSingleSlab.blockID, 9);
        		//(i + 11, j + 1, k + 18, Block.stoneSingleSlab.blockID, 9);
        		//(i + 11, j + 1, k + 19, -128, 6);
        		world.setBlock(i + 11, j + 1, k + 20, Block.sandStone.blockID);
        		//(i + 11, j + 1, k + 21, -128, 3);
        		//(i + 11, j + 4, k + 2, Block.stoneSingleSlab.blockID, 9);
        		//(i + 11, j + 4, k + 3, Block.stoneSingleSlab.blockID, 9);
        		//(i + 11, j + 4, k + 19, Block.stoneSingleSlab.blockID, 9);
        		//(i + 11, j + 4, k + 20, Block.stoneSingleSlab.blockID, 9);
        		world.setBlock(i + 11, j + 5, k + 3, Block.sandStone.blockID);
        		world.setBlock(i + 11, j + 5, k + 19, Block.sandStone.blockID);
        		world.setBlock(i + 11, j + 6, k + 4, Block.sandStone.blockID);
        		world.setBlock(i + 11, j + 6, k + 18, Block.sandStone.blockID);
        		world.setBlock(i + 11, j + 7, k + 4, Block.sandStone.blockID);
        		world.setBlock(i + 11, j + 7, k + 18, Block.sandStone.blockID);
        		world.setBlock(i + 11, j + 8, k + 5, Block.sandStone.blockID);
        		world.setBlock(i + 11, j + 8, k + 17, Block.sandStone.blockID);
        		world.setBlock(i + 11, j + 9, k + 5, Block.sandStone.blockID);
        		world.setBlock(i + 11, j + 9, k + 17, Block.sandStone.blockID);
        		world.setBlock(i + 11, j + 10, k + 6, Block.sandStone.blockID);
        		world.setBlock(i + 11, j + 10, k + 16, Block.sandStone.blockID);
        		world.setBlock(i + 11, j + 11, k + 6, Block.sandStone.blockID);
        		world.setBlock(i + 11, j + 11, k + 16, Block.sandStone.blockID);
        		world.setBlock(i + 11, j + 12, k + 7, Block.sandStone.blockID);
        		world.setBlock(i + 11, j + 12, k + 15, Block.sandStone.blockID);
        		world.setBlock(i + 11, j + 13, k + 7, Block.sandStone.blockID);
        		world.setBlock(i + 11, j + 13, k + 15, Block.sandStone.blockID);
        		world.setBlock(i + 11, j + 14, k + 8, Block.sandStone.blockID);
        		world.setBlock(i + 11, j + 14, k + 14, Block.sandStone.blockID);
        		world.setBlock(i + 11, j + 15, k + 8, Block.sandStone.blockID);
        		world.setBlock(i + 11, j + 15, k + 14, Block.sandStone.blockID);
        		world.setBlock(i + 11, j + 16, k + 9, Block.sandStone.blockID);
        		world.setBlock(i + 11, j + 16, k + 10, Block.glowStone.blockID);
        		world.setBlock(i + 11, j + 16, k + 11, Block.glowStone.blockID);
        		world.setBlock(i + 11, j + 16, k + 12, Block.glowStone.blockID);
        		world.setBlock(i + 11, j + 16, k + 13, Block.sandStone.blockID);
        		world.setBlock(i + 11, j + 17, k + 9, Block.sandStone.blockID);
        		world.setBlock(i + 11, j + 17, k + 13, Block.sandStone.blockID);
        		world.setBlock(i + 11, j + 18, k + 10, Block.sandStone.blockID);
        		world.setBlock(i + 11, j + 18, k + 11, Block.sandStone.blockID);
        		world.setBlock(i + 11, j + 18, k + 12, Block.sandStone.blockID);
        		world.setBlock(i + 11, j + 19, k + 10, Block.sandStone.blockID);
        		world.setBlock(i + 11, j + 19, k + 11, Block.sandStone.blockID);
        		world.setBlock(i + 11, j + 19, k + 12, Block.sandStone.blockID);
        		//(i + 12, j + 0, k + 0, -128, 2);
        		world.setBlock(i + 12, j + 0, k + 1, Block.sandStone.blockID);
        		world.setBlock(i + 12, j + 0, k + 2, Block.sandStone.blockID);
        		world.setBlock(i + 12, j + 0, k + 20, Block.sandStone.blockID);
        		world.setBlock(i + 12, j + 0, k + 21, Block.sandStone.blockID);
        		//(i + 12, j + 0, k + 22, -128, 3);
        		//(i + 12, j + 1, k + 1, -128, 2);
        		world.setBlock(i + 12, j + 1, k + 2, Block.sandStone.blockID);
        		//(i + 12, j + 1, k + 3, -128, 7);
        		//(i + 12, j + 1, k + 4, Block.stoneSingleSlab.blockID, 9);
        		//(i + 12, j + 1, k + 5, Block.stoneSingleSlab.blockID, 9);
        		//(i + 12, j + 1, k + 6, Block.stoneSingleSlab.blockID, 9);
        		//(i + 12, j + 1, k + 7, Block.stoneSingleSlab.blockID, 9);
        		//(i + 12, j + 1, k + 8, Block.stoneSingleSlab.blockID, 9);
        		//(i + 12, j + 1, k + 9, Block.stoneSingleSlab.blockID, 8);
        		//(i + 12, j + 1, k + 10, Block.stoneSingleSlab.blockID, 8);
        		//(i + 12, j + 1, k + 11, Block.stoneSingleSlab.blockID, 8);
        		//(i + 12, j + 1, k + 12, Block.stoneSingleSlab.blockID, 8);
        		//(i + 12, j + 1, k + 13, Block.stoneSingleSlab.blockID, 8);
        		//(i + 12, j + 1, k + 14, Block.stoneSingleSlab.blockID, 9);
        		//(i + 12, j + 1, k + 15, Block.stoneSingleSlab.blockID, 9);
        		//(i + 12, j + 1, k + 16, Block.stoneSingleSlab.blockID, 9);
        		//(i + 12, j + 1, k + 17, Block.stoneSingleSlab.blockID, 9);
        		//(i + 12, j + 1, k + 18, Block.stoneSingleSlab.blockID, 9);
        		//(i + 12, j + 1, k + 19, -128, 6);
        		world.setBlock(i + 12, j + 1, k + 20, Block.sandStone.blockID);
        		//(i + 12, j + 1, k + 21, -128, 3);
        		//(i + 12, j + 4, k + 2, -128, 4);
        		//(i + 12, j + 4, k + 3, -128, 4);
        		//(i + 12, j + 4, k + 19, -128, 4);
        		//(i + 12, j + 4, k + 20, -128, 4);
        		world.setBlock(i + 12, j + 5, k + 3, Block.sandStone.blockID);
        		world.setBlock(i + 12, j + 5, k + 19, Block.sandStone.blockID);
        		world.setBlock(i + 12, j + 6, k + 4, Block.sandStone.blockID);
        		world.setBlock(i + 12, j + 6, k + 18, Block.sandStone.blockID);
        		world.setBlock(i + 12, j + 7, k + 4, Block.sandStone.blockID);
        		world.setBlock(i + 12, j + 7, k + 18, Block.sandStone.blockID);
        		world.setBlock(i + 12, j + 8, k + 5, Block.sandStone.blockID);
        		world.setBlock(i + 12, j + 8, k + 17, Block.sandStone.blockID);
        		world.setBlock(i + 12, j + 9, k + 5, Block.sandStone.blockID);
        		world.setBlock(i + 12, j + 9, k + 17, Block.sandStone.blockID);
        		world.setBlock(i + 12, j + 10, k + 6, Block.sandStone.blockID);
        		world.setBlock(i + 12, j + 10, k + 16, Block.sandStone.blockID);
        		world.setBlock(i + 12, j + 11, k + 6, Block.sandStone.blockID);
        		world.setBlock(i + 12, j + 11, k + 16, Block.sandStone.blockID);
        		world.setBlock(i + 12, j + 12, k + 7, Block.sandStone.blockID);
        		world.setBlock(i + 12, j + 12, k + 15, Block.sandStone.blockID);
        		world.setBlock(i + 12, j + 13, k + 7, Block.sandStone.blockID);
        		world.setBlock(i + 12, j + 13, k + 15, Block.sandStone.blockID);
        		world.setBlock(i + 12, j + 14, k + 8, Block.sandStone.blockID);
        		world.setBlock(i + 12, j + 14, k + 14, Block.sandStone.blockID);
        		world.setBlock(i + 12, j + 15, k + 8, Block.sandStone.blockID);
        		world.setBlock(i + 12, j + 15, k + 14, Block.sandStone.blockID);
        		world.setBlock(i + 12, j + 16, k + 9, Block.sandStone.blockID);
        		world.setBlock(i + 12, j + 16, k + 10, Block.glowStone.blockID);
        		world.setBlock(i + 12, j + 16, k + 11, Block.glowStone.blockID);
        		world.setBlock(i + 12, j + 16, k + 12, Block.glowStone.blockID);
        		world.setBlock(i + 12, j + 16, k + 13, Block.sandStone.blockID);
        		world.setBlock(i + 12, j + 17, k + 9, Block.sandStone.blockID);
        		world.setBlock(i + 12, j + 17, k + 13, Block.sandStone.blockID);
        		world.setBlock(i + 12, j + 18, k + 10, Block.sandStone.blockID);
        		world.setBlock(i + 12, j + 18, k + 11, Block.sandStone.blockID);
        		world.setBlock(i + 12, j + 18, k + 12, Block.sandStone.blockID);
        		world.setBlock(i + 12, j + 19, k + 10, Block.sandStone.blockID);
        		world.setBlock(i + 12, j + 19, k + 11, Block.sandStone.blockID);
        		world.setBlock(i + 12, j + 19, k + 12, Block.sandStone.blockID);

        		world.setBlock(i + 13, j + 0, k + 1, Block.sandStone.blockID);
        		world.setBlock(i + 13, j + 0, k + 2, Block.sandStone.blockID);
        		world.setBlock(i + 13, j + 0, k + 3, Block.sandStone.blockID);
        		//(i + 13, j + 0, k + 9, Block.sandStone.blockID, 2);
        		//(i + 13, j + 0, k + 13, Block.sandStone.blockID, 2);
        		world.setBlock(i + 13, j + 0, k + 19, Block.sandStone.blockID);
        		world.setBlock(i + 13, j + 0, k + 20, Block.sandStone.blockID);
        		world.setBlock(i + 13, j + 0, k + 21, Block.sandStone.blockID);
        		world.setBlock(i + 13, j + 1, k + 2, Block.sandStone.blockID);
        		world.setBlock(i + 13, j + 1, k + 3, Block.sandStone.blockID);
        		//(i + 13, j + 1, k + 5, Block.stoneSingleSlab.blockID, 9);
        		//(i + 13, j + 1, k + 6, Block.stoneSingleSlab.blockID, 9);
        		//(i + 13, j + 1, k + 9, Block.sandStone.blockID, 2);
        		//(i + 13, j + 1, k + 10, Block.stoneSingleSlab.blockID, 8);
        		//(i + 13, j + 1, k + 11, Block.stoneSingleSlab.blockID, 8);
        		//(i + 13, j + 1, k + 12, Block.stoneSingleSlab.blockID, 8);
        		//(i + 13, j + 1, k + 13, Block.sandStone.blockID, 2);
        		//(i + 13, j + 1, k + 16, Block.stoneSingleSlab.blockID, 9);
        		//(i + 13, j + 1, k + 17, Block.stoneSingleSlab.blockID, 9);
        		world.setBlock(i + 13, j + 1, k + 19, Block.sandStone.blockID);
        		world.setBlock(i + 13, j + 1, k + 20, Block.sandStone.blockID);
        		world.setBlock(i + 13, j + 2, k + 2, Block.sandStone.blockID);
        		world.setBlock(i + 13, j + 2, k + 3, Block.sandStone.blockID);
        		//(i + 13, j + 2, k + 9, Block.sandStone.blockID, 2);
        		//(i + 13, j + 2, k + 13, Block.sandStone.blockID, 2);
        		world.setBlock(i + 13, j + 2, k + 19, Block.sandStone.blockID);
        		world.setBlock(i + 13, j + 2, k + 20, Block.sandStone.blockID);
        		world.setBlock(i + 13, j + 3, k + 2, Block.sandStone.blockID);
        		world.setBlock(i + 13, j + 3, k + 3, Block.sandStone.blockID);
        		//(i + 13, j + 3, k + 9, Block.sandStone.blockID, 1);
        		//(i + 13, j + 3, k + 13, Block.sandStone.blockID, 1);
        		world.setBlock(i + 13, j + 3, k + 19, Block.sandStone.blockID);
        		world.setBlock(i + 13, j + 3, k + 20, Block.sandStone.blockID);
        		world.setBlock(i + 13, j + 4, k + 2, Block.sandStone.blockID);
        		world.setBlock(i + 13, j + 4, k + 3, Block.sandStone.blockID);
        		world.setBlock(i + 13, j + 4, k + 19, Block.sandStone.blockID);
        		world.setBlock(i + 13, j + 4, k + 20, Block.sandStone.blockID);
        		world.setBlock(i + 13, j + 5, k + 3, Block.sandStone.blockID);
        		world.setBlock(i + 13, j + 5, k + 19, Block.sandStone.blockID);
        		world.setBlock(i + 13, j + 6, k + 4, Block.sandStone.blockID);
        		world.setBlock(i + 13, j + 6, k + 18, Block.sandStone.blockID);
        		world.setBlock(i + 13, j + 7, k + 4, Block.sandStone.blockID);
        		world.setBlock(i + 13, j + 7, k + 18, Block.sandStone.blockID);
        		world.setBlock(i + 13, j + 8, k + 5, Block.sandStone.blockID);
        		world.setBlock(i + 13, j + 8, k + 17, Block.sandStone.blockID);
        		world.setBlock(i + 13, j + 9, k + 5, Block.sandStone.blockID);
        		world.setBlock(i + 13, j + 9, k + 17, Block.sandStone.blockID);
        		world.setBlock(i + 13, j + 10, k + 6, Block.sandStone.blockID);
        		world.setBlock(i + 13, j + 10, k + 16, Block.sandStone.blockID);
        		world.setBlock(i + 13, j + 11, k + 6, Block.sandStone.blockID);
        		world.setBlock(i + 13, j + 11, k + 16, Block.sandStone.blockID);
        		world.setBlock(i + 13, j + 12, k + 7, Block.sandStone.blockID);
        		world.setBlock(i + 13, j + 12, k + 15, Block.sandStone.blockID);
        		world.setBlock(i + 13, j + 13, k + 7, Block.sandStone.blockID);
        		world.setBlock(i + 13, j + 13, k + 15, Block.sandStone.blockID);
        		world.setBlock(i + 13, j + 14, k + 8, Block.sandStone.blockID);
        		world.setBlock(i + 13, j + 14, k + 14, Block.sandStone.blockID);
        		world.setBlock(i + 13, j + 15, k + 8, Block.sandStone.blockID);
        		world.setBlock(i + 13, j + 15, k + 14, Block.sandStone.blockID);
        		world.setBlock(i + 13, j + 16, k + 9, Block.sandStone.blockID);
        		world.setBlock(i + 13, j + 16, k + 10, Block.sandStone.blockID);
        		world.setBlock(i + 13, j + 16, k + 11, Block.sandStone.blockID);
        		world.setBlock(i + 13, j + 16, k + 12, Block.sandStone.blockID);
        		world.setBlock(i + 13, j + 16, k + 13, Block.sandStone.blockID);
        		world.setBlock(i + 13, j + 17, k + 9, Block.sandStone.blockID);
        		world.setBlock(i + 13, j + 17, k + 10, Block.sandStone.blockID);
        		world.setBlock(i + 13, j + 17, k + 11, Block.sandStone.blockID);
        		world.setBlock(i + 13, j + 17, k + 12, Block.sandStone.blockID);
        		world.setBlock(i + 13, j + 17, k + 13, Block.sandStone.blockID);
        		world.setBlock(i + 14, j + 0, k + 1, Block.sandStone.blockID);
        		world.setBlock(i + 14, j + 0, k + 2, Block.sandStone.blockID);
        		world.setBlock(i + 14, j + 0, k + 20, Block.sandStone.blockID);
        		world.setBlock(i + 14, j + 0, k + 21, Block.sandStone.blockID);
        		world.setBlock(i + 14, j + 1, k + 1, Block.sandStone.blockID);
        		world.setBlock(i + 14, j + 1, k + 2, Block.sandStone.blockID);
        		//(i + 14, j + 1, k + 5, Block.stoneSingleSlab.blockID, 9);
        		//(i + 14, j + 1, k + 6, Block.stoneSingleSlab.blockID, 9);
        		//(i + 14, j + 1, k + 10, Block.stoneSingleSlab.blockID, 9);
        		//(i + 14, j + 1, k + 11, Block.stoneSingleSlab.blockID, 9);
        		//(i + 14, j + 1, k + 12, Block.stoneSingleSlab.blockID, 9);
        		//(i + 14, j + 1, k + 16, Block.stoneSingleSlab.blockID, 9);
        		//(i + 14, j + 1, k + 17, Block.stoneSingleSlab.blockID, 9);
        		world.setBlock(i + 14, j + 1, k + 20, Block.sandStone.blockID);
        		world.setBlock(i + 14, j + 1, k + 21, Block.sandStone.blockID);
        		world.setBlock(i + 14, j + 2, k + 2, Block.sandStone.blockID);
        		world.setBlock(i + 14, j + 2, k + 20, Block.sandStone.blockID);
        		world.setBlock(i + 14, j + 3, k + 2, Block.sandStone.blockID);
        		world.setBlock(i + 14, j + 3, k + 20, Block.sandStone.blockID);
        		world.setBlock(i + 14, j + 4, k + 3, Block.sandStone.blockID);
        		world.setBlock(i + 14, j + 4, k + 19, Block.sandStone.blockID);
        		world.setBlock(i + 14, j + 5, k + 3, Block.sandStone.blockID);
        		world.setBlock(i + 14, j + 5, k + 19, Block.sandStone.blockID);
        		world.setBlock(i + 14, j + 6, k + 4, Block.sandStone.blockID);
        		world.setBlock(i + 14, j + 6, k + 18, Block.sandStone.blockID);
        		world.setBlock(i + 14, j + 7, k + 4, Block.sandStone.blockID);
        		world.setBlock(i + 14, j + 7, k + 18, Block.sandStone.blockID);
        		world.setBlock(i + 14, j + 8, k + 5, Block.sandStone.blockID);
        		world.setBlock(i + 14, j + 8, k + 17, Block.sandStone.blockID);
        		world.setBlock(i + 14, j + 9, k + 5, Block.sandStone.blockID);
        		world.setBlock(i + 14, j + 9, k + 17, Block.sandStone.blockID);
        		world.setBlock(i + 14, j + 10, k + 6, Block.sandStone.blockID);
        		world.setBlock(i + 14, j + 10, k + 16, Block.sandStone.blockID);
        		world.setBlock(i + 14, j + 11, k + 6, Block.sandStone.blockID);
        		world.setBlock(i + 14, j + 11, k + 16, Block.sandStone.blockID);
        		world.setBlock(i + 14, j + 12, k + 7, Block.sandStone.blockID);
        		world.setBlock(i + 14, j + 12, k + 15, Block.sandStone.blockID);
        		world.setBlock(i + 14, j + 13, k + 7, Block.sandStone.blockID);
        		world.setBlock(i + 14, j + 13, k + 15, Block.sandStone.blockID);
        		world.setBlock(i + 14, j + 14, k + 8, Block.sandStone.blockID);
        		world.setBlock(i + 14, j + 14, k + 9, Block.sandStone.blockID);
        		world.setBlock(i + 14, j + 14, k + 10, Block.sandStone.blockID);
        		world.setBlock(i + 14, j + 14, k + 11, Block.sandStone.blockID);
        		world.setBlock(i + 14, j + 14, k + 12, Block.sandStone.blockID);
        		world.setBlock(i + 14, j + 14, k + 13, Block.sandStone.blockID);
        		world.setBlock(i + 14, j + 14, k + 14, Block.sandStone.blockID);
        		world.setBlock(i + 14, j + 15, k + 8, Block.sandStone.blockID);
        		world.setBlock(i + 14, j + 15, k + 9, Block.sandStone.blockID);
        		world.setBlock(i + 14, j + 15, k + 10, Block.sandStone.blockID);
        		world.setBlock(i + 14, j + 15, k + 11, Block.sandStone.blockID);
        		world.setBlock(i + 14, j + 15, k + 12, Block.sandStone.blockID);
        		world.setBlock(i + 14, j + 15, k + 13, Block.sandStone.blockID);
        		world.setBlock(i + 14, j + 15, k + 14, Block.sandStone.blockID);
        		world.setBlock(i + 15, j + 0, k + 1, Block.sandStone.blockID);
        		world.setBlock(i + 15, j + 0, k + 2, Block.sandStone.blockID);
        		world.setBlock(i + 15, j + 0, k + 20, Block.sandStone.blockID);
        		world.setBlock(i + 15, j + 0, k + 21, Block.sandStone.blockID);
        		world.setBlock(i + 15, j + 1, k + 1, Block.sandStone.blockID);
        		world.setBlock(i + 15, j + 1, k + 2, Block.sandStone.blockID);
        		//(i + 15, j + 1, k + 5, Block.stoneSingleSlab.blockID, 9);
        		//(i + 15, j + 1, k + 6, Block.stoneSingleSlab.blockID, 9);
        		//(i + 15, j + 1, k + 10, Block.stoneSingleSlab.blockID, 9);
        		//(i + 15, j + 1, k + 11, Block.stoneSingleSlab.blockID, 9);
        		//(i + 15, j + 1, k + 12, Block.stoneSingleSlab.blockID, 9);
        		//(i + 15, j + 1, k + 16, Block.stoneSingleSlab.blockID, 9);
        		//(i + 15, j + 1, k + 17, Block.stoneSingleSlab.blockID, 9);
        		world.setBlock(i + 15, j + 1, k + 20, Block.sandStone.blockID);
        		world.setBlock(i + 15, j + 1, k + 21, Block.sandStone.blockID);
        		world.setBlock(i + 15, j + 2, k + 2, Block.sandStone.blockID);
        		world.setBlock(i + 15, j + 2, k + 20, Block.sandStone.blockID);
        		world.setBlock(i + 15, j + 3, k + 2, Block.sandStone.blockID);
        		world.setBlock(i + 15, j + 3, k + 20, Block.sandStone.blockID);
        		world.setBlock(i + 15, j + 4, k + 3, Block.sandStone.blockID);
        		world.setBlock(i + 15, j + 4, k + 19, Block.sandStone.blockID);
        		world.setBlock(i + 15, j + 5, k + 3, Block.sandStone.blockID);
        		world.setBlock(i + 15, j + 5, k + 19, Block.sandStone.blockID);
        		world.setBlock(i + 15, j + 6, k + 4, Block.sandStone.blockID);
        		world.setBlock(i + 15, j + 6, k + 18, Block.sandStone.blockID);
        		world.setBlock(i + 15, j + 7, k + 4, Block.sandStone.blockID);
        		world.setBlock(i + 15, j + 7, k + 18, Block.sandStone.blockID);
        		world.setBlock(i + 15, j + 8, k + 5, Block.sandStone.blockID);
        		world.setBlock(i + 15, j + 8, k + 17, Block.sandStone.blockID);
        		world.setBlock(i + 15, j + 9, k + 5, Block.sandStone.blockID);
        		world.setBlock(i + 15, j + 9, k + 17, Block.sandStone.blockID);
        		world.setBlock(i + 15, j + 10, k + 6, Block.sandStone.blockID);
        		world.setBlock(i + 15, j + 10, k + 16, Block.sandStone.blockID);
        		world.setBlock(i + 15, j + 11, k + 6, Block.sandStone.blockID);
        		world.setBlock(i + 15, j + 11, k + 16, Block.sandStone.blockID);
        		world.setBlock(i + 15, j + 12, k + 7, Block.sandStone.blockID);
        		world.setBlock(i + 15, j + 12, k + 8, Block.sandStone.blockID);
        		world.setBlock(i + 15, j + 12, k + 9, Block.sandStone.blockID);
        		world.setBlock(i + 15, j + 12, k + 10, Block.sandStone.blockID);
        		world.setBlock(i + 15, j + 12, k + 11, Block.sandStone.blockID);
        		world.setBlock(i + 15, j + 12, k + 12, Block.sandStone.blockID);
        		world.setBlock(i + 15, j + 12, k + 13, Block.sandStone.blockID);
        		world.setBlock(i + 15, j + 12, k + 14, Block.sandStone.blockID);
        		world.setBlock(i + 15, j + 12, k + 15, Block.sandStone.blockID);
        		world.setBlock(i + 15, j + 13, k + 7, Block.sandStone.blockID);
        		world.setBlock(i + 15, j + 13, k + 8, Block.sandStone.blockID);
        		world.setBlock(i + 15, j + 13, k + 9, Block.sandStone.blockID);
        		world.setBlock(i + 15, j + 13, k + 10, Block.sandStone.blockID);
        		world.setBlock(i + 15, j + 13, k + 11, Block.sandStone.blockID);
        		world.setBlock(i + 15, j + 13, k + 12, Block.sandStone.blockID);
        		world.setBlock(i + 15, j + 13, k + 13, Block.sandStone.blockID);
        		world.setBlock(i + 15, j + 13, k + 14, Block.sandStone.blockID);
        		world.setBlock(i + 15, j + 13, k + 15, Block.sandStone.blockID);
        		world.setBlock(i + 16, j + 0, k + 1, Block.sandStone.blockID);
        		world.setBlock(i + 16, j + 0, k + 2, Block.sandStone.blockID);
        		world.setBlock(i + 16, j + 0, k + 20, Block.sandStone.blockID);
        		world.setBlock(i + 16, j + 0, k + 21, Block.sandStone.blockID);
        		world.setBlock(i + 16, j + 1, k + 1, Block.sandStone.blockID);
        		world.setBlock(i + 16, j + 1, k + 2, Block.sandStone.blockID);
        		//(i + 16, j + 1, k + 3, -128, 7);
        		//(i + 16, j + 1, k + 4, Block.stoneSingleSlab.blockID, 9);
        		//(i + 16, j + 1, k + 5, Block.stoneSingleSlab.blockID, 9);
        		//(i + 16, j + 1, k + 6, Block.stoneSingleSlab.blockID, 9);
        		//(i + 16, j + 1, k + 7, Block.stoneSingleSlab.blockID, 9);
        		//(i + 16, j + 1, k + 8, Block.stoneSingleSlab.blockID, 9);
        		//(i + 16, j + 1, k + 9, Block.stoneSingleSlab.blockID, 9);
        		//(i + 16, j + 1, k + 10, Block.stoneSingleSlab.blockID, 9);
        		//(i + 16, j + 1, k + 11, Block.stoneSingleSlab.blockID, 9);
        		//(i + 16, j + 1, k + 12, Block.stoneSingleSlab.blockID, 9);
        		//(i + 16, j + 1, k + 13, Block.stoneSingleSlab.blockID, 9);
        		//(i + 16, j + 1, k + 14, Block.stoneSingleSlab.blockID, 9);
        		//(i + 16, j + 1, k + 15, Block.stoneSingleSlab.blockID, 9);
        		//(i + 16, j + 1, k + 16, Block.stoneSingleSlab.blockID, 9);
        		//(i + 16, j + 1, k + 17, Block.stoneSingleSlab.blockID, 9);
        		//(i + 16, j + 1, k + 18, Block.stoneSingleSlab.blockID, 9);
        		//(i + 16, j + 1, k + 19, -128, 6);
        		world.setBlock(i + 16, j + 1, k + 20, Block.sandStone.blockID);
        		world.setBlock(i + 16, j + 1, k + 21, Block.sandStone.blockID);
        		world.setBlock(i + 16, j + 2, k + 2, Block.sandStone.blockID);
        		world.setBlock(i + 16, j + 2, k + 20, Block.sandStone.blockID);
        		world.setBlock(i + 16, j + 3, k + 2, Block.sandStone.blockID);
        		world.setBlock(i + 16, j + 3, k + 20, Block.sandStone.blockID);
        		world.setBlock(i + 16, j + 4, k + 3, Block.sandStone.blockID);
        		world.setBlock(i + 16, j + 4, k + 19, Block.sandStone.blockID);
        		world.setBlock(i + 16, j + 5, k + 3, Block.sandStone.blockID);
        		world.setBlock(i + 16, j + 5, k + 19, Block.sandStone.blockID);
        		world.setBlock(i + 16, j + 6, k + 4, Block.sandStone.blockID);
        		world.setBlock(i + 16, j + 6, k + 18, Block.sandStone.blockID);
        		world.setBlock(i + 16, j + 7, k + 4, Block.sandStone.blockID);
        		world.setBlock(i + 16, j + 7, k + 18, Block.sandStone.blockID);
        		world.setBlock(i + 16, j + 8, k + 5, Block.sandStone.blockID);
        		world.setBlock(i + 16, j + 8, k + 17, Block.sandStone.blockID);
        		world.setBlock(i + 16, j + 9, k + 5, Block.sandStone.blockID);
        		world.setBlock(i + 16, j + 9, k + 17, Block.sandStone.blockID);
        		world.setBlock(i + 16, j + 10, k + 6, Block.sandStone.blockID);
        		world.setBlock(i + 16, j + 10, k + 7, Block.sandStone.blockID);
        		world.setBlock(i + 16, j + 10, k + 8, Block.sandStone.blockID);
        		world.setBlock(i + 16, j + 10, k + 9, Block.sandStone.blockID);
        		world.setBlock(i + 16, j + 10, k + 10, Block.sandStone.blockID);
        		world.setBlock(i + 16, j + 10, k + 11, Block.sandStone.blockID);
        		world.setBlock(i + 16, j + 10, k + 12, Block.sandStone.blockID);
        		world.setBlock(i + 16, j + 10, k + 13, Block.sandStone.blockID);
        		world.setBlock(i + 16, j + 10, k + 14, Block.sandStone.blockID);
        		world.setBlock(i + 16, j + 10, k + 15, Block.sandStone.blockID);
        		world.setBlock(i + 16, j + 10, k + 16, Block.sandStone.blockID);
        		world.setBlock(i + 16, j + 11, k + 6, Block.sandStone.blockID);
        		world.setBlock(i + 16, j + 11, k + 7, Block.sandStone.blockID);
        		world.setBlock(i + 16, j + 11, k + 8, Block.sandStone.blockID);
        		world.setBlock(i + 16, j + 11, k + 9, Block.sandStone.blockID);
        		world.setBlock(i + 16, j + 11, k + 10, Block.sandStone.blockID);
        		world.setBlock(i + 16, j + 11, k + 11, Block.sandStone.blockID);
        		world.setBlock(i + 16, j + 11, k + 12, Block.sandStone.blockID);
        		world.setBlock(i + 16, j + 11, k + 13, Block.sandStone.blockID);
        		world.setBlock(i + 16, j + 11, k + 14, Block.sandStone.blockID);
        		world.setBlock(i + 16, j + 11, k + 15, Block.sandStone.blockID);
        		world.setBlock(i + 16, j + 11, k + 16, Block.sandStone.blockID);
        		world.setBlock(i + 17, j + 0, k + 1, Block.sandStone.blockID);
        		world.setBlock(i + 17, j + 0, k + 2, Block.sandStone.blockID);
        		world.setBlock(i + 17, j + 0, k + 20, Block.sandStone.blockID);
        		world.setBlock(i + 17, j + 0, k + 21, Block.sandStone.blockID);
        		world.setBlock(i + 17, j + 1, k + 1, Block.sandStone.blockID);
        		world.setBlock(i + 17, j + 1, k + 2, Block.sandStone.blockID);
        		//(i + 17, j + 1, k + 3, -128, 7);
        		//(i + 17, j + 1, k + 4, Block.stoneSingleSlab.blockID, 9);
        		//(i + 17, j + 1, k + 5, Block.stoneSingleSlab.blockID, 9);
        		//(i + 17, j + 1, k + 6, Block.stoneSingleSlab.blockID, 9);
        		//(i + 17, j + 1, k + 7, Block.stoneSingleSlab.blockID, 9);
        		//(i + 17, j + 1, k + 8, Block.stoneSingleSlab.blockID, 9);
        		//(i + 17, j + 1, k + 9, Block.stoneSingleSlab.blockID, 9);
        		//(i + 17, j + 1, k + 10, Block.stoneSingleSlab.blockID, 9);
        		//(i + 17, j + 1, k + 11, Block.stoneSingleSlab.blockID, 9);
        		//(i + 17, j + 1, k + 12, Block.stoneSingleSlab.blockID, 9);
        		//(i + 17, j + 1, k + 13, Block.stoneSingleSlab.blockID, 9);
        		//(i + 17, j + 1, k + 14, Block.stoneSingleSlab.blockID, 9);
        		//(i + 17, j + 1, k + 15, Block.stoneSingleSlab.blockID, 9);
        		//(i + 17, j + 1, k + 16, Block.stoneSingleSlab.blockID, 9);
        		//(i + 17, j + 1, k + 17, Block.stoneSingleSlab.blockID, 9);
        		//(i + 17, j + 1, k + 18, Block.stoneSingleSlab.blockID, 9);
        		//(i + 17, j + 1, k + 19, -128, 6);
        		world.setBlock(i + 17, j + 1, k + 20, Block.sandStone.blockID);
        		world.setBlock(i + 17, j + 1, k + 21, Block.sandStone.blockID);
        		world.setBlock(i + 17, j + 2, k + 2, Block.sandStone.blockID);
        		world.setBlock(i + 17, j + 2, k + 20, Block.sandStone.blockID);
        		world.setBlock(i + 17, j + 3, k + 2, Block.sandStone.blockID);
        		world.setBlock(i + 17, j + 3, k + 20, Block.sandStone.blockID);
        		world.setBlock(i + 17, j + 4, k + 3, Block.sandStone.blockID);
        		world.setBlock(i + 17, j + 4, k + 19, Block.sandStone.blockID);
        		world.setBlock(i + 17, j + 5, k + 3, Block.sandStone.blockID);
        		world.setBlock(i + 17, j + 5, k + 19, Block.sandStone.blockID);
        		world.setBlock(i + 17, j + 6, k + 4, Block.sandStone.blockID);
        		world.setBlock(i + 17, j + 6, k + 18, Block.sandStone.blockID);
        		world.setBlock(i + 17, j + 7, k + 4, Block.sandStone.blockID);
        		world.setBlock(i + 17, j + 7, k + 18, Block.sandStone.blockID);
        		world.setBlock(i + 17, j + 8, k + 5, Block.sandStone.blockID);
        		world.setBlock(i + 17, j + 8, k + 6, Block.sandStone.blockID);
        		world.setBlock(i + 17, j + 8, k + 7, Block.sandStone.blockID);
        		world.setBlock(i + 17, j + 8, k + 8, Block.sandStone.blockID);
        		world.setBlock(i + 17, j + 8, k + 9, Block.sandStone.blockID);
        		world.setBlock(i + 17, j + 8, k + 10, Block.sandStone.blockID);
        		world.setBlock(i + 17, j + 8, k + 11, Block.sandStone.blockID);
        		world.setBlock(i + 17, j + 8, k + 12, Block.sandStone.blockID);
        		world.setBlock(i + 17, j + 8, k + 13, Block.sandStone.blockID);
        		world.setBlock(i + 17, j + 8, k + 14, Block.sandStone.blockID);
        		world.setBlock(i + 17, j + 8, k + 15, Block.sandStone.blockID);
        		world.setBlock(i + 17, j + 8, k + 16, Block.sandStone.blockID);
        		world.setBlock(i + 17, j + 8, k + 17, Block.sandStone.blockID);
        		world.setBlock(i + 17, j + 9, k + 5, Block.sandStone.blockID);
        		world.setBlock(i + 17, j + 9, k + 6, Block.sandStone.blockID);
        		world.setBlock(i + 17, j + 9, k + 7, Block.sandStone.blockID);
        		world.setBlock(i + 17, j + 9, k + 8, Block.sandStone.blockID);
        		world.setBlock(i + 17, j + 9, k + 9, Block.sandStone.blockID);
        		world.setBlock(i + 17, j + 9, k + 10, Block.sandStone.blockID);
        		world.setBlock(i + 17, j + 9, k + 11, Block.sandStone.blockID);
        		world.setBlock(i + 17, j + 9, k + 12, Block.sandStone.blockID);
        		world.setBlock(i + 17, j + 9, k + 13, Block.sandStone.blockID);
        		world.setBlock(i + 17, j + 9, k + 14, Block.sandStone.blockID);
        		world.setBlock(i + 17, j + 9, k + 15, Block.sandStone.blockID);
        		world.setBlock(i + 17, j + 9, k + 16, Block.sandStone.blockID);
        		world.setBlock(i + 17, j + 9, k + 17, Block.sandStone.blockID);
        		world.setBlock(i + 18, j + 0, k + 1, Block.sandStone.blockID);
        		world.setBlock(i + 18, j + 0, k + 2, Block.sandStone.blockID);
        		world.setBlock(i + 18, j + 0, k + 20, Block.sandStone.blockID);
        		world.setBlock(i + 18, j + 0, k + 21, Block.sandStone.blockID);
        		world.setBlock(i + 18, j + 1, k + 1, Block.sandStone.blockID);
        		world.setBlock(i + 18, j + 1, k + 2, Block.sandStone.blockID);
        		//(i + 18, j + 1, k + 5, Block.stoneSingleSlab.blockID, 9);
        		//(i + 18, j + 1, k + 6, Block.stoneSingleSlab.blockID, 9);
        		//(i + 18, j + 1, k + 10, Block.stoneSingleSlab.blockID, 9);
        		//(i + 18, j + 1, k + 11, Block.stoneSingleSlab.blockID, 9);
        		//(i + 18, j + 1, k + 12, Block.stoneSingleSlab.blockID, 9);
        		//(i + 18, j + 1, k + 16, Block.stoneSingleSlab.blockID, 9);
        		//(i + 18, j + 1, k + 17, Block.stoneSingleSlab.blockID, 9);
        		world.setBlock(i + 18, j + 1, k + 20, Block.sandStone.blockID);
        		world.setBlock(i + 18, j + 1, k + 21, Block.sandStone.blockID);
        		world.setBlock(i + 18, j + 2, k + 2, Block.sandStone.blockID);
        		world.setBlock(i + 18, j + 2, k + 20, Block.sandStone.blockID);
        		world.setBlock(i + 18, j + 3, k + 2, Block.sandStone.blockID);
        		world.setBlock(i + 18, j + 3, k + 20, Block.sandStone.blockID);
        		world.setBlock(i + 18, j + 4, k + 3, Block.sandStone.blockID);
        		world.setBlock(i + 18, j + 4, k + 19, Block.sandStone.blockID);
        		world.setBlock(i + 18, j + 5, k + 3, Block.sandStone.blockID);
        		world.setBlock(i + 18, j + 5, k + 19, Block.sandStone.blockID);
        		world.setBlock(i + 18, j + 6, k + 4, Block.sandStone.blockID);
        		world.setBlock(i + 18, j + 6, k + 5, Block.sandStone.blockID);
        		world.setBlock(i + 18, j + 6, k + 6, Block.sandStone.blockID);
        		world.setBlock(i + 18, j + 6, k + 7, Block.sandStone.blockID);
        		world.setBlock(i + 18, j + 6, k + 8, Block.sandStone.blockID);
        		world.setBlock(i + 18, j + 6, k + 9, Block.sandStone.blockID);
        		world.setBlock(i + 18, j + 6, k + 10, Block.sandStone.blockID);
        		world.setBlock(i + 18, j + 6, k + 11, Block.sandStone.blockID);
        		world.setBlock(i + 18, j + 6, k + 12, Block.sandStone.blockID);
        		world.setBlock(i + 18, j + 6, k + 13, Block.sandStone.blockID);
        		world.setBlock(i + 18, j + 6, k + 14, Block.sandStone.blockID);
        		world.setBlock(i + 18, j + 6, k + 15, Block.sandStone.blockID);
        		world.setBlock(i + 18, j + 6, k + 16, Block.sandStone.blockID);
        		world.setBlock(i + 18, j + 6, k + 17, Block.sandStone.blockID);
        		world.setBlock(i + 18, j + 6, k + 18, Block.sandStone.blockID);
        		world.setBlock(i + 18, j + 7, k + 4, Block.sandStone.blockID);
        		world.setBlock(i + 18, j + 7, k + 5, Block.sandStone.blockID);
        		world.setBlock(i + 18, j + 7, k + 6, Block.sandStone.blockID);
        		world.setBlock(i + 18, j + 7, k + 7, Block.sandStone.blockID);
        		world.setBlock(i + 18, j + 7, k + 8, Block.sandStone.blockID);
        		world.setBlock(i + 18, j + 7, k + 9, Block.sandStone.blockID);
        		world.setBlock(i + 18, j + 7, k + 10, Block.sandStone.blockID);
        		world.setBlock(i + 18, j + 7, k + 11, Block.sandStone.blockID);
        		world.setBlock(i + 18, j + 7, k + 12, Block.sandStone.blockID);
        		world.setBlock(i + 18, j + 7, k + 13, Block.sandStone.blockID);
        		world.setBlock(i + 18, j + 7, k + 14, Block.sandStone.blockID);
        		world.setBlock(i + 18, j + 7, k + 15, Block.sandStone.blockID);
        		world.setBlock(i + 18, j + 7, k + 16, Block.sandStone.blockID);
        		world.setBlock(i + 18, j + 7, k + 17, Block.sandStone.blockID);
        		world.setBlock(i + 18, j + 7, k + 18, Block.sandStone.blockID);
        		world.setBlock(i + 19, j + 0, k + 1, Block.sandStone.blockID);
        		world.setBlock(i + 19, j + 0, k + 2, Block.sandStone.blockID);
        		world.setBlock(i + 19, j + 0, k + 9, Block.sandStone.blockID);
        		world.setBlock(i + 19, j + 0, k + 13, Block.sandStone.blockID);
        		world.setBlock(i + 19, j + 0, k + 20, Block.sandStone.blockID);
        		world.setBlock(i + 19, j + 0, k + 21, Block.sandStone.blockID);
        		world.setBlock(i + 19, j + 1, k + 1, Block.sandStone.blockID);
        		world.setBlock(i + 19, j + 1, k + 2, Block.sandStone.blockID);
        		//(i + 19, j + 1, k + 5, -128, 4);
        		//(i + 19, j + 1, k + 6, -128, 4);
        		world.setBlock(i + 19, j + 1, k + 9, Block.sandStone.blockID);
        		//(i + 19, j + 1, k + 10, -128, 4);
        		//(i + 19, j + 1, k + 11, -128, 4);
        		//(i + 19, j + 1, k + 12, -128, 4);
        		world.setBlock(i + 19, j + 1, k + 13, Block.sandStone.blockID);
        		//(i + 19, j + 1, k + 16, -128, 4);
        		//(i + 19, j + 1, k + 17, -128, 4);
        		world.setBlock(i + 19, j + 1, k + 20, Block.sandStone.blockID);
        		world.setBlock(i + 19, j + 1, k + 21, Block.sandStone.blockID);
        		world.setBlock(i + 19, j + 2, k + 2, Block.sandStone.blockID);
        		world.setBlock(i + 19, j + 2, k + 9, Block.sandStone.blockID);
        		world.setBlock(i + 19, j + 2, k + 13, Block.sandStone.blockID);
        		world.setBlock(i + 19, j + 2, k + 20, Block.sandStone.blockID);
        		world.setBlock(i + 19, j + 3, k + 2, Block.sandStone.blockID);
        		world.setBlock(i + 19, j + 3, k + 9, Block.sandStone.blockID);
        		world.setBlock(i + 19, j + 3, k + 13, Block.sandStone.blockID);
        		world.setBlock(i + 19, j + 3, k + 20, Block.sandStone.blockID);
        		world.setBlock(i + 19, j + 4, k + 3, Block.sandStone.blockID);
        		world.setBlock(i + 19, j + 4, k + 4, Block.sandStone.blockID);
        		world.setBlock(i + 19, j + 4, k + 5, Block.sandStone.blockID);
        		world.setBlock(i + 19, j + 4, k + 6, Block.sandStone.blockID);
        		world.setBlock(i + 19, j + 4, k + 7, Block.sandStone.blockID);
        		world.setBlock(i + 19, j + 4, k + 8, Block.sandStone.blockID);
        		world.setBlock(i + 19, j + 4, k + 9, Block.sandStone.blockID);
        		//(i + 19, j + 4, k + 10, -128, 7);
        		//(i + 19, j + 4, k + 11, Block.stoneSingleSlab.blockID, 9);
        		//(i + 19, j + 4, k + 12, -128, 6);
        		world.setBlock(i + 19, j + 4, k + 13, Block.sandStone.blockID);
        		world.setBlock(i + 19, j + 4, k + 14, Block.sandStone.blockID);
        		world.setBlock(i + 19, j + 4, k + 15, Block.sandStone.blockID);
        		world.setBlock(i + 19, j + 4, k + 16, Block.sandStone.blockID);
        		world.setBlock(i + 19, j + 4, k + 17, Block.sandStone.blockID);
        		world.setBlock(i + 19, j + 4, k + 18, Block.sandStone.blockID);
        		world.setBlock(i + 19, j + 4, k + 19, Block.sandStone.blockID);
        		world.setBlock(i + 19, j + 5, k + 3, Block.sandStone.blockID);
        		world.setBlock(i + 19, j + 5, k + 4, Block.sandStone.blockID);
        		world.setBlock(i + 19, j + 5, k + 5, Block.sandStone.blockID);
        		world.setBlock(i + 19, j + 5, k + 6, Block.sandStone.blockID);
        		world.setBlock(i + 19, j + 5, k + 7, Block.sandStone.blockID);
        		world.setBlock(i + 19, j + 5, k + 8, Block.sandStone.blockID);
        		world.setBlock(i + 19, j + 5, k + 9, Block.sandStone.blockID);
        		world.setBlock(i + 19, j + 5, k + 10, Block.sandStone.blockID);
        		world.setBlock(i + 19, j + 5, k + 11, Block.sandStone.blockID);
        		world.setBlock(i + 19, j + 5, k + 12, Block.sandStone.blockID);
        		world.setBlock(i + 19, j + 5, k + 13, Block.sandStone.blockID);
        		world.setBlock(i + 19, j + 5, k + 14, Block.sandStone.blockID);
        		world.setBlock(i + 19, j + 5, k + 15, Block.sandStone.blockID);
        		world.setBlock(i + 19, j + 5, k + 16, Block.sandStone.blockID);
        		world.setBlock(i + 19, j + 5, k + 17, Block.sandStone.blockID);
        		world.setBlock(i + 19, j + 5, k + 18, Block.sandStone.blockID);
        		world.setBlock(i + 19, j + 5, k + 19, Block.sandStone.blockID);
        		world.setBlock(i + 20, j + 0, k + 1, Block.sandStone.blockID);
        		world.setBlock(i + 20, j + 0, k + 2, Block.sandStone.blockID);
        		world.setBlock(i + 20, j + 0, k + 3, Block.sandStone.blockID);
        		world.setBlock(i + 20, j + 0, k + 4, Block.sandStone.blockID);
        		world.setBlock(i + 20, j + 0, k + 5, Block.sandStone.blockID);
        		world.setBlock(i + 20, j + 0, k + 6, Block.sandStone.blockID);
        		world.setBlock(i + 20, j + 0, k + 7, Block.sandStone.blockID);
        		world.setBlock(i + 20, j + 0, k + 8, Block.sandStone.blockID);
        		world.setBlock(i + 20, j + 0, k + 9, Block.sandStone.blockID);
        		world.setBlock(i + 20, j + 0, k + 10, Block.sandStone.blockID);
        		world.setBlock(i + 20, j + 0, k + 11, Block.sandStone.blockID);
        		world.setBlock(i + 20, j + 0, k + 12, Block.sandStone.blockID);
        		world.setBlock(i + 20, j + 0, k + 13, Block.sandStone.blockID);
        		world.setBlock(i + 20, j + 0, k + 14, Block.sandStone.blockID);
        		world.setBlock(i + 20, j + 0, k + 15, Block.sandStone.blockID);
        		world.setBlock(i + 20, j + 0, k + 16, Block.sandStone.blockID);
        		world.setBlock(i + 20, j + 0, k + 17, Block.sandStone.blockID);
        		world.setBlock(i + 20, j + 0, k + 18, Block.sandStone.blockID);
        		world.setBlock(i + 20, j + 0, k + 19, Block.sandStone.blockID);
        		world.setBlock(i + 20, j + 0, k + 20, Block.sandStone.blockID);
        		world.setBlock(i + 20, j + 0, k + 21, Block.sandStone.blockID);
        		world.setBlock(i + 20, j + 1, k + 1, Block.sandStone.blockID);
        		world.setBlock(i + 20, j + 1, k + 2, Block.sandStone.blockID);
        		world.setBlock(i + 20, j + 1, k + 3, Block.sandStone.blockID);
        		world.setBlock(i + 20, j + 1, k + 4, Block.sandStone.blockID);
        		world.setBlock(i + 20, j + 1, k + 5, Block.sandStone.blockID);
        		world.setBlock(i + 20, j + 1, k + 6, Block.sandStone.blockID);
        		world.setBlock(i + 20, j + 1, k + 7, Block.sandStone.blockID);
        		world.setBlock(i + 20, j + 1, k + 8, Block.sandStone.blockID);
        		world.setBlock(i + 20, j + 1, k + 9, Block.sandStone.blockID);
        		world.setBlock(i + 20, j + 1, k + 10, Block.sandStone.blockID);
        		world.setBlock(i + 20, j + 1, k + 11, Block.sandStone.blockID);
        		world.setBlock(i + 20, j + 1, k + 12, Block.sandStone.blockID);
        		world.setBlock(i + 20, j + 1, k + 13, Block.sandStone.blockID);
        		world.setBlock(i + 20, j + 1, k + 14, Block.sandStone.blockID);
        		world.setBlock(i + 20, j + 1, k + 15, Block.sandStone.blockID);
        		world.setBlock(i + 20, j + 1, k + 16, Block.sandStone.blockID);
        		world.setBlock(i + 20, j + 1, k + 17, Block.sandStone.blockID);
        		world.setBlock(i + 20, j + 1, k + 18, Block.sandStone.blockID);
        		world.setBlock(i + 20, j + 1, k + 19, Block.sandStone.blockID);
        		world.setBlock(i + 20, j + 1, k + 20, Block.sandStone.blockID);
        		world.setBlock(i + 20, j + 1, k + 21, Block.sandStone.blockID);
        		world.setBlock(i + 20, j + 2, k + 2, Block.sandStone.blockID);
        		world.setBlock(i + 20, j + 2, k + 3, Block.sandStone.blockID);
        		world.setBlock(i + 20, j + 2, k + 4, Block.sandStone.blockID);
        		world.setBlock(i + 20, j + 2, k + 5, Block.sandStone.blockID);
        		world.setBlock(i + 20, j + 2, k + 6, Block.sandStone.blockID);
        		world.setBlock(i + 20, j + 2, k + 7, Block.sandStone.blockID);
        		world.setBlock(i + 20, j + 2, k + 8, Block.sandStone.blockID);
        		world.setBlock(i + 20, j + 2, k + 9, Block.sandStone.blockID);
        		world.setBlock(i + 20, j + 2, k + 13, Block.sandStone.blockID);
        		world.setBlock(i + 20, j + 2, k + 14, Block.sandStone.blockID);
        		world.setBlock(i + 20, j + 2, k + 15, Block.sandStone.blockID);
        		world.setBlock(i + 20, j + 2, k + 16, Block.sandStone.blockID);
        		world.setBlock(i + 20, j + 2, k + 17, Block.sandStone.blockID);
        		world.setBlock(i + 20, j + 2, k + 18, Block.sandStone.blockID);
        		world.setBlock(i + 20, j + 2, k + 19, Block.sandStone.blockID);
        		world.setBlock(i + 20, j + 2, k + 20, Block.sandStone.blockID);
        		world.setBlock(i + 20, j + 3, k + 2, Block.sandStone.blockID);
        		world.setBlock(i + 20, j + 3, k + 3, Block.sandStone.blockID);
        		world.setBlock(i + 20, j + 3, k + 4, Block.sandStone.blockID);
        		world.setBlock(i + 20, j + 3, k + 5, Block.sandStone.blockID);
        		world.setBlock(i + 20, j + 3, k + 6, Block.sandStone.blockID);
        		world.setBlock(i + 20, j + 3, k + 7, Block.sandStone.blockID);
        		world.setBlock(i + 20, j + 3, k + 8, Block.sandStone.blockID);
        		world.setBlock(i + 20, j + 3, k + 9, Block.sandStone.blockID);
        		world.setBlock(i + 20, j + 3, k + 13, Block.sandStone.blockID);
        		world.setBlock(i + 20, j + 3, k + 14, Block.sandStone.blockID);
        		world.setBlock(i + 20, j + 3, k + 15, Block.sandStone.blockID);
        		world.setBlock(i + 20, j + 3, k + 16, Block.sandStone.blockID);
        		world.setBlock(i + 20, j + 3, k + 17, Block.sandStone.blockID);
        		world.setBlock(i + 20, j + 3, k + 18, Block.sandStone.blockID);
        		world.setBlock(i + 20, j + 3, k + 19, Block.sandStone.blockID);
        		world.setBlock(i + 20, j + 3, k + 20, Block.sandStone.blockID);
        		world.setBlock(i + 20, j + 4, k + 9, Block.sandStone.blockID);
        		//(i + 20, j + 4, k + 10, -128, 7);
        		//(i + 20, j + 4, k + 11, Block.stoneSingleSlab.blockID, 9);
        		//(i + 20, j + 4, k + 12, -128, 6);
        		world.setBlock(i + 20, j + 4, k + 13, Block.sandStone.blockID);
        		world.setBlock(i + 21, j + 0, k + 1, Block.sandStone.blockID);
        		world.setBlock(i + 21, j + 0, k + 2, Block.sandStone.blockID);
        		world.setBlock(i + 21, j + 0, k + 3, Block.sandStone.blockID);
        		world.setBlock(i + 21, j + 0, k + 4, Block.sandStone.blockID);
        		world.setBlock(i + 21, j + 0, k + 5, Block.sandStone.blockID);
        		world.setBlock(i + 21, j + 0, k + 6, Block.sandStone.blockID);
        		world.setBlock(i + 21, j + 0, k + 7, Block.sandStone.blockID);
        		world.setBlock(i + 21, j + 0, k + 8, Block.sandStone.blockID);
        		world.setBlock(i + 21, j + 0, k + 9, Block.sandStone.blockID);
        		world.setBlock(i + 21, j + 0, k + 10, Block.sandStone.blockID);
        		world.setBlock(i + 21, j + 0, k + 11, Block.sandStone.blockID);
        		world.setBlock(i + 21, j + 0, k + 12, Block.sandStone.blockID);
        		world.setBlock(i + 21, j + 0, k + 13, Block.sandStone.blockID);
        		world.setBlock(i + 21, j + 0, k + 14, Block.sandStone.blockID);
        		world.setBlock(i + 21, j + 0, k + 15, Block.sandStone.blockID);
        		world.setBlock(i + 21, j + 0, k + 16, Block.sandStone.blockID);
        		world.setBlock(i + 21, j + 0, k + 17, Block.sandStone.blockID);
        		world.setBlock(i + 21, j + 0, k + 18, Block.sandStone.blockID);
        		world.setBlock(i + 21, j + 0, k + 19, Block.sandStone.blockID);
        		world.setBlock(i + 21, j + 0, k + 20, Block.sandStone.blockID);
        		world.setBlock(i + 21, j + 0, k + 21, Block.sandStone.blockID);
        		world.setBlock(i + 21, j + 1, k + 1, Block.sandStone.blockID);
        		world.setBlock(i + 21, j + 1, k + 2, Block.sandStone.blockID);
        		world.setBlock(i + 21, j + 1, k + 3, Block.sandStone.blockID);
        		world.setBlock(i + 21, j + 1, k + 4, Block.sandStone.blockID);
        		world.setBlock(i + 21, j + 1, k + 5, Block.sandStone.blockID);
        		world.setBlock(i + 21, j + 1, k + 6, Block.sandStone.blockID);
        		world.setBlock(i + 21, j + 1, k + 7, Block.sandStone.blockID);
        		world.setBlock(i + 21, j + 1, k + 8, Block.sandStone.blockID);
        		//(i + 21, j + 1, k + 9, -128, 3);
        		//(i + 21, j + 1, k + 10, -128, 1);
        		//(i + 21, j + 1, k + 11, -128, 1);
        		//(i + 21, j + 1, k + 12, -128, 1);
        		//(i + 21, j + 1, k + 13, -128, 2);
        		world.setBlock(i + 21, j + 1, k + 14, Block.sandStone.blockID);
        		world.setBlock(i + 21, j + 1, k + 15, Block.sandStone.blockID);
        		world.setBlock(i + 21, j + 1, k + 16, Block.sandStone.blockID);
        		world.setBlock(i + 21, j + 1, k + 17, Block.sandStone.blockID);
        		world.setBlock(i + 21, j + 1, k + 18, Block.sandStone.blockID);
        		world.setBlock(i + 21, j + 1, k + 19, Block.sandStone.blockID);
        		world.setBlock(i + 21, j + 1, k + 20, Block.sandStone.blockID);
        		world.setBlock(i + 21, j + 1, k + 21, Block.sandStone.blockID);
        		//(i + 22, j + 0, k + 9, -128, 3);
        		//(i + 22, j + 0, k + 10, -128, 1);
        		//(i + 22, j + 0, k + 11, -128, 1);
        		//(i + 22, j + 0, k + 12, -128, 1);
        		//(i + 22, j + 0, k + 13, -128, 2);

		

		return true;
	}
		else{
			return false;
		}
}
}